Workbook

Sheet Start Here
A1: Membership Pricing Calculator
A2: Made by a licensed esthetician. Works in Excel, Google Sheets and Numbers.
A4: HOW TO USE IT
A5: Step 1 | B5: Go to the Calculator tab. Put in your monthly costs (rent, insurance, software and so on).
A6: Step 2 | B6: Set up to three tiers: the price, the facial that's included, what it costs you to do, and the perks.
A7: Step 3 | B7: Read The Answers: what each member is worth, how many you need to cover your costs, and how many to pay you.
A8: Step 4 | B8: Open Your First Year to see how fast you get there with steady sign-ups and a few cancellations.
A9: Step 5 | B9: Use Price Test to compare prices before you announce them.
A11: WHICH CELLS TO CHANGE
A12: Blue text | B12: Your numbers. Change these.
A13: Yellow cell | B13: The most important inputs.
A14: Black text | B14: Calculated for you. Leave these alone.
A16: GOOD TO KNOW
A17: The example numbers are modeled on a small studio in Los Angeles. They are a starting point, not advice. Every number in blue is yours to change.
A19: MADE BY
A20: Evelyn Romero, licensed esthetician, Lumevina Aesthetics. Questions? Message us on Etsy.

Sheet Calculator
A1: Membership Calculator
A2: Every blue number is an example. Replace it with yours.
A4: YOUR MONTHLY COSTS
A5: Rent and utilities | B5: 1400 | E5: Suite or room rent, plus power and water if you pay them.
A6: Insurance and license | B6: 65 | E6: Liability insurance and license renewals, spread monthly.
A7: Booking software and website | B7: 120 | E7: Booking app, website, email, phone.
A8: Marketing | B8: 150 | E8: Ads, printing, promotions.
A9: Laundry and small supplies | B9: 60 | E9: Linens and disposables not tied to one service.
A10: Other | B10: 0 | E10: Anything else you pay every month.
A11: Total monthly costs | B11: =SUM(B5:B10) -> 1795
A13: CARD FEES
A14: Percent of each charge | B14: 0.029 | E14: A typical online card rate (Stripe, Square). Check your own processor.
A15: Fixed fee per charge | B15: 0.3
A17: YOUR MEMBERSHIP TIERS | B17: TIER 1 | C17: TIER 2 | D17: TIER 3
A18: Name | B18: Glow | C18: Glow Plus | D18: Ageless | E18: What clients will see.
A19: Monthly price | B19: 119 | C19: 159 | D19: 209 | E19: What the member pays each month.
A20: Included service: your single price | B20: 140 | C20: 185 | D20: 245 | E20: What the included facial costs without a membership.
A21: Minutes per included service | B21: 60 | C21: 75 | D21: 90 | E21: Treatment time, including turnover.
A22: Product used per service (your cost) | B22: 12 | C22: 16 | D22: 22 | E22: Backbar product used in the treatment.
A23: Members who use it each month | B23: 0.85 | C23: 0.85 | D23: 0.9 | E23: Not everyone comes every month. 85% is common.
A24: Discount on products | B24: 0.1 | C24: 0.1 | D24: 0.15 | E24: Member perk on retail.
A25: Average product spend a month | B25: 30 | C25: 35 | D25: 45 | E25: Retail a typical member buys each month.
A26: Discount on add-ons | B26: 0.15 | C26: 0.15 | D26: 0.15 | E26: Member perk on add-ons.
A27: Average add-on spend a month | B27: 15 | C27: 20 | D27: 25 | E27: Add-ons a typical member books each month.
A28: Share of members on this tier | B28: 0.5 | C28: 0.35 | D28: 0.15 | E28: Your best guess. The three should add up to 100%.
A29: Mix check (should be 100%) | B29: =SUM(B28:D28) -> 1 | C29: =IF(ROUND(B29,4)=1,"Good","Adjust the mix") -> Good
A31: WHAT EACH MEMBER IS WORTH
A32: Card fee | B32: =B19*$B$14+$B$15 -> 3.751 | C32: =C19*$B$14+$B$15 -> 4.911 | D32: =D19*$B$14+$B$15 -> 6.361 | E32: On each monthly charge.
A33: Product for the included service | B33: =B22*B23 -> 10.2 | C33: =C22*C23 -> 13.6 | D33: =D22*D23 -> 19.8 | E33: Product cost times how often it's used.
A34: Perks you give | B34: =B25*B24+B27*B26 -> 5.25 | C34: =C25*C24+C27*C26 -> 6.5 | D34: =D25*D24+D27*D26 -> 10.5 | E34: The discounts, in dollars.
A35: You keep per member, per month | B35: =B19-B32-B33-B34 -> 99.799 | C35: =C19-C32-C33-C34 -> 133.989 | D35: =D19-D32-D33-D34 -> 172.339 | E35: Before rent and other monthly costs.
A36: Member saves on each visit | B36: =B20-B19 -> 21 | C36: =C20-C19 -> 26 | D36: =D20-D19 -> 36 | E36: What makes the membership an easy yes.
A37: Member's discount | B37: =IF(B20=0,0,1-B19/B20) -> 0.15 | C37: =IF(C20=0,0,1-C19/C20) -> 0.14054054 | D37: =IF(D20=0,0,1-D19/D20) -> 0.14693878 | E37: 10% to 25% feels generous and stays profitable.
A38: You keep per hour of treatment | B38: =IF(B21*B23=0,0,B35/(B21*B23/60)) -> 117.41059 | C38: =IF(C21*C23=0,0,C35/(C21*C23/60)) -> 126.10729 | D38: =IF(D21*D23=0,0,D35/(D21*D23/60)) -> 127.65852 | E38: Compare with what a regular hour earns you.
A40: THE ANSWERS
A41: Average you keep per member (your mix) | B41: =IF(SUM(B28:D28)=0,0,SUMPRODUCT(B35:D35,B28:D28)/SUM(B28:D28)) -> 122.6465
A42: Members to cover your monthly costs | B42: =IF(B41<=0,"Raise prices",ROUNDUP(B11/B41,0)) -> 15 | E42: Your break-even: the membership alone pays the bills.
A43: Your monthly pay goal, before taxes | B43: 4000 | E43: What you want the membership to pay you each month.
A44: Members to cover costs and your pay | B44: =IF(B41<=0,"Raise prices",ROUNDUP((B11+B43)/B41,0)) -> 48
A45: Monthly dues from that many members | B45: =IF(ISNUMBER(B44),B44*SUMPRODUCT(B19:D19,B28:D28)/SUM(B28:D28),0) -> 7032
...

Sheet Your First Year
A1: Your First Year
A2: How the membership grows with steady sign-ups and a few cancellations.
A4: ASSUMPTIONS
A5: Starting members | C5: 0
A6: Cancel each month | C6: 0.04 | E6: 3% to 5% a month is typical for a well-run membership.
A7: Average dues | C7: =IF(SUM(Calculator!B28:D28)=0,0,SUMPRODUCT(Calculator!B19:D19,Calculator!B28:D28)/SUM(Calculator!B28:D28)) -> 146.5 | E7: Green numbers come from the Calculator tab.
A8: You keep per member | C8: =Calculator!B41 -> 122.6465
A9: Monthly costs | C9: =Calculator!B11 -> 1795
A11: MONTH | B11: START | C11: NEW SIGN-UPS | D11: CANCELLED | E11: END | F11: DUES | G11: YOU KEEP | H11: MONTHLY COSTS | I11: NET | J11: RUNNING TOTAL | K11: COVERS COSTS
A12: 1 | B12: =C5 -> 0 | C12: 4 | D12: =B12*$C$6 -> 0 | E12: =B12+C12-D12 -> 4 | F12: =E12*$C$7 -> 586 | G12: =E12*$C$8 -> 490.586 | H12: =$C$9 -> 1795 | I12: =G12-H12 -> -1304.414 | J12: =I12 -> -1304.414 | K12: =IF(I12>=0,"Yes","Not yet") -> Not yet
A13: 2 | B13: =E12 -> 4 | C13: 5 | D13: =B13*$C$6 -> 0.16 | E13: =B13+C13-D13 -> 8.84 | F13: =E13*$C$7 -> 1295.06 | G13: =E13*$C$8 -> 1084.1951 | H13: =$C$9 -> 1795 | I13: =G13-H13 -> -710.80494 | J13: =J12+I13 -> -2015.2189 | K13: =IF(I13>=0,"Yes","Not yet") -> Not yet
A14: 3 | B14: =E13 -> 8.84 | C14: 6 | D14: =B14*$C$6 -> 0.3536 | E14: =B14+C14-D14 -> 14.4864 | F14: =E14*$C$7 -> 2122.2576 | G14: =E14*$C$8 -> 1776.7063 | H14: =$C$9 -> 1795 | I14: =G14-H14 -> -18.293742 | J14: =J13+I14 -> -2033.5127 | K14: =IF(I14>=0,"Yes","Not yet") -> Not yet
A15: 4 | B15: =E14 -> 14.4864 | C15: 6 | D15: =B15*$C$6 -> 0.579456 | E15: =B15+C15-D15 -> 19.906944 | F15: =E15*$C$7 -> 2916.3673 | G15: =E15*$C$8 -> 2441.517 | H15: =$C$9 -> 1795 | I15: =G15-H15 -> 646.51701 | J15: =J14+I15 -> -1386.9957 | K15: =IF(I15>=0,"Yes","Not yet") -> Yes
A16: 5 | B16: =E15 -> 19.906944 | C16: 6 | D16: =B16*$C$6 -> 0.79627776 | E16: =B16+C16-D16 -> 25.110666 | F16: =E16*$C$7 -> 3678.7126 | G16: =E16*$C$8 -> 3079.7353 | H16: =$C$9 -> 1795 | I16: =G16-H16 -> 1284.7353 | J16: =J15+I16 -> -102.26035 | K16: =IF(I16>=0,"Yes","Not yet") -> Yes
A17: 6 | B17: =E16 -> 25.110666 | C17: 6 | D17: =B17*$C$6 -> 1.0044266 | E17: =B17+C17-D17 -> 30.10624 | F17: =E17*$C$7 -> 4410.5641 | G17: =E17*$C$8 -> 3692.4249 | H17: =$C$9 -> 1795 | I17: =G17-H17 -> 1897.4249 | J17: =J16+I17 -> 1795.1646 | K17: =IF(I17>=0,"Yes","Not yet") -> Yes
A18: 7 | B18: =E17 -> 30.10624 | C18: 6 | D18: =B18*$C$6 -> 1.2042496 | E18: =B18+C18-D18 -> 34.90199 | F18: =E18*$C$7 -> 5113.1415 | G18: =E18*$C$8 -> 4280.6069 | H18: =$C$9 -> 1795 | I18: =G18-H18 -> 2485.6069 | J18: =J17+I18 -> 4280.7715 | K18: =IF(I18>=0,"Yes","Not yet") -> Yes
A19: 8 | B19: =E18 -> 34.90199 | C19: 6 | D19: =B19*$C$6 -> 1.3960796 | E19: =B19+C19-D19 -> 39.50591 | F19: =E19*$C$7 -> 5787.6159 | G19: =E19*$C$8 -> 4845.2616 | H19: =$C$9 -> 1795 | I19: =G19-H19 -> 3050.2616 | J19: =J18+I19 -> 7331.0331 | K19: =IF(I19>=0,"Yes","Not yet") -> Yes
A20: 9 | B20: =E19 -> 39.50591 | C20: 6 | D20: =B20*$C$6 -> 1.5802364 | E20: =B20+C20-D20 -> 43.925674 | F20: =E20*$C$7 -> 6435.1112 | G20: =E20*$C$8 -> 5387.3302 | H20: =$C$9 -> 1795 | I20: =G20-H20 -> 3592.3302 | J20: =J19+I20 -> 10923.363 | K20: =IF(I20>=0,"Yes","Not yet") -> Yes
A21: 10 | B21: =E20 -> 43.925674 | C21: 6 | D21: =B21*$C$6 -> 1.757027 | E21: =B21+C21-D21 -> 48.168647 | F21: =E21*$C$7 -> 7056.7068 | G21: =E21*$C$8 -> 5907.716 | H21: =$C$9 -> 1795 | I21: =G21-H21 -> 4112.716 | J21: =J20+I21 -> 15036.079 | K21: =IF(I21>=0,"Yes","Not yet") -> Yes
A22: 11 | B22: =E21 -> 48.168647 | C22: 6 | D22: =B22*$C$6 -> 1.9267459 | E22: =B22+C22-D22 -> 52.241901 | F22: =E22*$C$7 -> 7653.4385 | G22: =E22*$C$8 -> 6407.2863 | H22: =$C$9 -> 1795 | I22: =G22-H22 -> 4612.2863 | J22: =J21+I22 -> 19648.366 | K22: =IF(I22>=0,"Yes","Not yet") -> Yes
A23: 12 | B23: =E22 -> 52.241901 | C23: 6 | D23: =B23*$C$6 -> 2.089676 | E23: =B23+C23-D23 -> 56.152225 | F23: =E23*$C$7 -> 8226.301 | G23: =E23*$C$8 -> 6886.8739 | H23: =$C$9 -> 1795 | I23: =G23-H23 -> 5091.8739 | J23: =J22+I23 -> 24740.239 | K23: =IF(I23>=0,"Yes","Not yet") -> Yes
C24: New sign-ups are blue: change any month.
A26: AFTER TWELVE MONTHS
A27: Members | D27: =E23 -> 56.152225
A28: Monthly dues | D28: =F23 -> 8226.301
A29: First month the membership covers your costs | D29: =IF(COUNTIF(K12:K23,"Yes")=0,"Not yet",INDEX(A12:A23,MATCH("Yes",K12:K23,0))) -> 4

Sheet Price Test
A1: Price Test
A2: Monthly profit from Tier 1 at different prices and member counts, after your monthly costs.
B4: PRICE ↓ MEMBERS → | C4: 10 | D4: 20 | E4: 30 | F4: 40 | G4: 50 | H4: 60
B5: 89 | C5: =C$4*($B5-($B5*Calculator!$B$14+Calculator!$B$15)-Calculator!$B$33-Calculator!$B$34)-Calculator!$B$11 -> -1088.31 | D5: =D$4*($B5-($B5*Calculator!$B$14+Calculator!$B$15)-Calculator!$B$33-Calculator!$B$34)-Calculator!$B$11 -> -381.62 | E5: =E$4*($B5-($B5*Calculator!$B$14+Calculator!$B$15)-Calculator!$B$33-Calculator!$B$34)-Calculator!$B$11 -> 325.07 | F5: =F$4*($B5-($B5*Calculator!$B$14+Calculator!$B$15)-Calculator!$B$33-Calculator!$B$34)-Calculator!$B$11 -> 1031.76 | G5: =G$4*($B5-($B5*Calculator!$B$14+Calculator!$B$15)-Calculator!$B$33-Calculator!$B$34)-Calculator!$B$11 -> 1738.45 | H5: =H$4*($B5-($B5*Calculator!$B$14+Calculator!$B$15)-Calculator!$B$33-Calculator!$B$34)-Calculator!$B$11 -> 2445.14
B6: 99 | C6: =C$4*($B6-($B6*Calculator!$B$14+Calculator!$B$15)-Calculator!$B$33-Calculator!$B$34)-Calculator!$B$11 -> -991.21 | D6: =D$4*($B6-($B6*Calculator!$B$14+Calculator!$B$15)-Calculator!$B$33-Calculator!$B$34)-Calculator!$B$11 -> -187.42 | E6: =E$4*($B6-($B6*Calculator!$B$14+Calculator!$B$15)-Calculator!$B$33-Calculator!$B$34)-Calculator!$B$11 -> 616.37 | F6: =F$4*($B6-($B6*Calculator!$B$14+Calculator!$B$15)-Calculator!$B$33-Calculator!$B$34)-Calculator!$B$11 -> 1420.16 | G6: =G$4*($B6-($B6*Calculator!$B$14+Calculator!$B$15)-Calculator!$B$33-Calculator!$B$34)-Calculator!$B$11 -> 2223.95 | H6: =H$4*($B6-($B6*Calculator!$B$14+Calculator!$B$15)-Calculator!$B$33-Calculator!$B$34)-Calculator!$B$11 -> 3027.74
B7: 109 | C7: =C$4*($B7-($B7*Calculator!$B$14+Calculator!$B$15)-Calculator!$B$33-Calculator!$B$34)-Calculator!$B$11 -> -894.11 | D7: =D$4*($B7-($B7*Calculator!$B$14+Calculator!$B$15)-Calculator!$B$33-Calculator!$B$34)-Calculator!$B$11 -> 6.78 | E7: =E$4*($B7-($B7*Calculator!$B$14+Calculator!$B$15)-Calculator!$B$33-Calculator!$B$34)-Calculator!$B$11 -> 907.67 | F7: =F$4*($B7-($B7*Calculator!$B$14+Calculator!$B$15)-Calculator!$B$33-Calculator!$B$34)-Calculator!$B$11 -> 1808.56 | G7: =G$4*($B7-($B7*Calculator!$B$14+Calculator!$B$15)-Calculator!$B$33-Calculator!$B$34)-Calculator!$B$11 -> 2709.45 | H7: =H$4*($B7-($B7*Calculator!$B$14+Calculator!$B$15)-Calculator!$B$33-Calculator!$B$34)-Calculator!$B$11 -> 3610.34
B8: 119 | C8: =C$4*($B8-($B8*Calculator!$B$14+Calculator!$B$15)-Calculator!$B$33-Calculator!$B$34)-Calculator!$B$11 -> -797.01 | D8: =D$4*($B8-($B8*Calculator!$B$14+Calculator!$B$15)-Calculator!$B$33-Calculator!$B$34)-Calculator!$B$11 -> 200.98 | E8: =E$4*($B8-($B8*Calculator!$B$14+Calculator!$B$15)-Calculator!$B$33-Calculator!$B$34)-Calculator!$B$11 -> 1198.97 | F8: =F$4*($B8-($B8*Calculator!$B$14+Calculator!$B$15)-Calculator!$B$33-Calculator!$B$34)-Calculator!$B$11 -> 2196.96 | G8: =G$4*($B8-($B8*Calculator!$B$14+Calculator!$B$15)-Calculator!$B$33-Calculator!$B$34)-Calculator!$B$11 -> 3194.95 | H8: =H$4*($B8-($B8*Calculator!$B$14+Calculator!$B$15)-Calculator!$B$33-Calculator!$B$34)-Calculator!$B$11 -> 4192.94
B9: 129 | C9: =C$4*($B9-($B9*Calculator!$B$14+Calculator!$B$15)-Calculator!$B$33-Calculator!$B$34)-Calculator!$B$11 -> -699.91 | D9: =D$4*($B9-($B9*Calculator!$B$14+Calculator!$B$15)-Calculator!$B$33-Calculator!$B$34)-Calculator!$B$11 -> 395.18 | E9: =E$4*($B9-($B9*Calculator!$B$14+Calculator!$B$15)-Calculator!$B$33-Calculator!$B$34)-Calculator!$B$11 -> 1490.27 | F9: =F$4*($B9-($B9*Calculator!$B$14+Calculator!$B$15)-Calculator!$B$33-Calculator!$B$34)-Calculator!$B$11 -> 2585.36 | G9: =G$4*($B9-($B9*Calculator!$B$14+Calculator!$B$15)-Calculator!$B$33-Calculator!$B$34)-Calculator!$B$11 -> 3680.45 | H9: =H$4*($B9-($B9*Calculator!$B$14+Calculator!$B$15)-Calculator!$B$33-Calculator!$B$34)-Calculator!$B$11 -> 4775.54
B10: 139 | C10: =C$4*($B10-($B10*Calculator!$B$14+Calculator!$B$15)-Calculator!$B$33-Calculator!$B$34)-Calculator!$B$11 -> -602.81 | D10: =D$4*($B10-($B10*Calculator!$B$14+Calculator!$B$15)-Calculator!$B$33-Calculator!$B$34)-Calculator!$B$11 -> 589.38 | E10: =E$4*($B10-($B10*Calculator!$B$14+Calculator!$B$15)-Calculator!$B$33-Calculator!$B$34)-Calculator!$B$11 -> 1781.57 | F10: =F$4*($B10-($B10*Calculator!$B$14+Calculator!$B$15)-Calculator!$B$33-Calculator!$B$34)-Calculator!$B$11 -> 2973.76 | G10: =G$4*($B10-($B10*Calculator!$B$14+Calculator!$B$15)-Calculator!$B$33-Calculator!$B$34)-Calculator!$B$11 -> 4165.95 | H10: =H$4*($B10-($B10*Calculator!$B$14+Calculator!$B$15)-Calculator!$B$33-Calculator!$B$34)-Calculator!$B$11 -> 5358.14
B11: 149 | C11: =C$4*($B11-($B11*Calculator!$B$14+Calculator!$B$15)-Calculator!$B$33-Calculator!$B$34)-Calculator!$B$11 -> -505.71 | D11: =D$4*($B11-($B11*Calculator!$B$14+Calculator!$B$15)-Calculator!$B$33-Calculator!$B$34)-Calculator!$B$11 -> 783.58 | E11: =E$4*($B11-($B11*Calculator!$B$14+Calculator!$B$15)-Calculator!$B$33-Calculator!$B$34)-Calculator!$B$11 -> 2072.87 | F11: =F$4*($B11-($B11*Calculator!$B$14+Calculator!$B$15)-Calculator!$B$33-Calculator!$B$34)-Calculator!$B$11 -> 3362.16 | G11: =G$4*($B11-($B11*Calculator!$B$14+Calculator!$B$15)-Calculator!$B$33-Calculator!$B$34)-Calculator!$B$11 -> 4651.45 | H11: =H$4*($B11-($B11*Calculator!$B$14+Calculator!$B$15)-Calculator!$B$33-Calculator!$B$34)-Calculator!$B$11 -> 5940.74
B12: 159 | C12: =C$4*($B12-($B12*Calculator!$B$14+Calculator!$B$15)-Calculator!$B$33-Calculator!$B$34)-Calculator!$B$11 -> -408.61 | D12: =D$4*($B12-($B12*Calculator!$B$14+Calculator!$B$15)-Calculator!$B$33-Calculator!$B$34)-Calculator!$B$11 -> 977.78 | E12: =E$4*($B12-($B12*Calculator!$B$14+Calculator!$B$15)-Calculator!$B$33-Calculator!$B$34)-Calculator!$B$11 -> 2364.17 | F12: =F$4*($B12-($B12*Calculator!$B$14+Calculator!$B$15)-Calculator!$B$33-Calculator!$B$34)-Calculator!$B$11 -> 3750.56 | G12: =G$4*($B12-($B12*Calculator!$B$14+Calculator!$B$15)-Calculator!$B$33-Calculator!$B$34)-Calculator!$B$11 -> 5136.95 | H12: =H$4*($B12-($B12*Calculator!$B$14+Calculator!$B$15)-Calculator!$B$33-Calculator!$B$34)-Calculator!$B$11 -> 6523.34
B13: 169 | C13: =C$4*($B13-($B13*Calculator!$B$14+Calculator!$B$15)-Calculator!$B$33-Calculator!$B$34)-Calculator!$B$11 -> -311.51 | D13: =D$4*($B13-($B13*Calculator!$B$14+Calculator!$B$15)-Calculator!$B$33-Calculator!$B$34)-Calculator!$B$11 -> 1171.98 | E13: =E$4*($B13-($B13*Calculator!$B$14+Calculator!$B$15)-Calculator!$B$33-Calculator!$B$34)-Calculator!$B$11 -> 2655.47 | F13: =F$4*($B13-($B13*Calculator!$B$14+Calculator!$B$15)-Calculator!$B$33-Calculator!$B$34)-Calculator!$B$11 -> 4138.96 | G13: =G$4*($B13-($B13*Calculator!$B$14+Calculator!$B$15)-Calculator!$B$33-Calculator!$B$34)-Calculator!$B$11 -> 5622.45 | H13: =H$4*($B13-($B13*Calculator!$B$14+Calculator!$B$15)-Calculator!$B$33-Calculator!$B$34)-Calculator!$B$11 -> 7105.94
B14: 179 | C14: =C$4*($B14-($B14*Calculator!$B$14+Calculator!$B$15)-Calculator!$B$33-Calculator!$B$34)-Calculator!$B$11 -> -214.41 | D14: =D$4*($B14-($B14*Calculator!$B$14+Calculator!$B$15)-Calculator!$B$33-Calculator!$B$34)-Calculator!$B$11 -> 1366.18 | E14: =E$4*($B14-($B14*Calculator!$B$14+Calculator!$B$15)-Calculator!$B$33-Calculator!$B$34)-Calculator!$B$11 -> 2946.77 | F14: =F$4*($B14-($B14*Calculator!$B$14+Calculator!$B$15)-Calculator!$B$33-Calculator!$B$34)-Calculator!$B$11 -> 4527.36 | G14: =G$4*($B14-($B14*Calculator!$B$14+Calculator!$B$15)-Calculator!$B$33-Calculator!$B$34)-Calculator!$B$11 -> 6107.95 | H14: =H$4*($B14-($B14*Calculator!$B$14+Calculator!$B$15)-Calculator!$B$33-Calculator!$B$34)-Calculator!$B$11 -> 7688.54
B15: 189 | C15: =C$4*($B15-($B15*Calculator!$B$14+Calculator!$B$15)-Calculator!$B$33-Calculator!$B$34)-Calculator!$B$11 -> -117.31 | D15: =D$4*($B15-($B15*Calculator!$B$14+Calculator!$B$15)-Calculator!$B$33-Calculator!$B$34)-Calculator!$B$11 -> 1560.38 | E15: =E$4*($B15-($B15*Calculator!$B$14+Calculator!$B$15)-Calculator!$B$33-Calculator!$B$34)-Calculator!$B$11 -> 3238.07 | F15: =F$4*($B15-($B15*Calculator!$B$14+Calculator!$B$15)-Calculator!$B$33-Calculator!$B$34)-Calculator!$B$11 -> 4915.76 | G15: =G$4*($B15-($B15*Calculator!$B$14+Calculator!$B$15)-Calculator!$B$33-Calculator!$B$34)-Calculator!$B$11 -> 6593.45 | H15: =H$4*($B15-($B15*Calculator!$B$14+Calculator!$B$15)-Calculator!$B$33-Calculator!$B$34)-Calculator!$B$11 -> 8271.14
B16: 199 | C16: =C$4*($B16-($B16*Calculator!$B$14+Calculator!$B$15)-Calculator!$B$33-Calculator!$B$34)-Calculator!$B$11 -> -20.21 | D16: =D$4*($B16-($B16*Calculator!$B$14+Calculator!$B$15)-Calculator!$B$33-Calculator!$B$34)-Calculator!$B$11 -> 1754.58 | E16: =E$4*($B16-($B16*Calculator!$B$14+Calculator!$B$15)-Calculator!$B$33-Calculator!$B$34)-Calculator!$B$11 -> 3529.37 | F16: =F$4*($B16-($B16*Calculator!$B$14+Calculator!$B$15)-Calculator!$B$33-Calculator!$B$34)-Calculator!$B$11 -> 5304.16 | G16: =G$4*($B16-($B16*Calculator!$B$14+Calculator!$B$15)-Calculator!$B$33-Calculator!$B$34)-Calculator!$B$11 -> 7078.95 | H16: =H$4*($B16-($B16*Calculator!$B$14+Calculator!$B$15)-Calculator!$B$33-Calculator!$B$34)-Calculator!$B$11 -> 8853.74
B18: Uses Tier 1's product, perk and card-fee numbers from the Calculator tab. Red: the membership doesn't cover your monthly costs yet. Green: it does.
B19: The prices and member counts in blue can be changed.
