Workbook

Sheet Start Here
A1: Bookkeeping & Profit Tracker
A2: Made by a licensed esthetician. Works in Excel, Google Sheets and Numbers.
A4: HOW TO USE IT
A5: Step 1 | B5: Open Settings. Put in the year, your card fee and how much to set aside for taxes. Rename the categories if you like.
A6: Step 2 | B6: Every sale goes on the Income tab: date, client, what, category, amount, tip and how they paid.
A7: Step 3 | B7: Every business cost goes on the Expenses tab, with its category. Save the receipt.
A8: Step 4 | B8: List your retail products on the Products tab to see margins and when to reorder.
A9: Step 5 | B9: Month by Month and The Year at a Glance fill themselves in. Check them on the first of each month.
A11: WHICH CELLS TO CHANGE
A12: Blue text | B12: Your numbers. Change these.
A13: Yellow cell | B13: The most important inputs.
A14: Black text | B14: Calculated for you. Leave these alone.
A16: GOOD TO KNOW
A17: The first line of Income and Expenses is an example. Type over it. This tracker helps you stay organized and is not tax advice; share it with your tax preparer.
A19: MADE BY
A20: Evelyn Romero, licensed esthetician, Lumevina Aesthetics. Questions? Message us on Etsy.

Sheet Settings
A1: Settings
A2: Set these once. The lists feed the drop-downs on the other tabs.
A4: YOUR BUSINESS
A5: Business name | B5: Your Studio Name
A6: Year | B6: 2026
A7: Set aside for taxes | B7: 0.25 | D7: Ask your tax preparer for your number.
A8: Card fee, percent | B8: 0.029 | D8: Your processor's rate (Square, Stripe, etc.).
A9: Card fee, per charge | B9: 0.3
A11: INCOME CATEGORIES | D11: EXPENSE CATEGORIES | F11: WAYS TO PAY
A12: Facials | D12: Rent and utilities | F12: Card
A13: Peels and advanced | D13: Backbar supplies | F13: Cash
A14: Waxing | D14: Retail inventory | F14: Venmo or Zelle
A15: Lash and brow | D15: Equipment | F15: Gift card
A16: Memberships | D16: Insurance and licenses | F16: Other
A17: Products | D17: Software and booking
A18: Gift cards sold | D18: Marketing
A19: Other services | D19: Education
D20: Laundry and cleaning
D21: Bank fees
D22: Phone and internet
D23: Car and mileage
D24: Other
A26: Rename categories to fit your studio; keep the same number of rows so the totals stay linked.

Sheet Income
A1: Income
A2: One line per sale. Tips and card fees are worked out for you.
A3: Example on the first line: replace it with your first sale. Blue columns are yours; black ones fill themselves in.
A5: DATE | B5: CLIENT | C5: WHAT | D5: CATEGORY | E5: AMOUNT | F5: TIP | G5: PAID BY | H5: CARD FEE | I5: YOU KEEP | J5: MONTH
A6: 46028 | B6: Maria G. | C6: Signature Facial | D6: Facials | E6: 125 | F6: 20 | G6: Card | H6: =IF(G6="Card",ROUND((E6+F6)*Settings!$B$8+Settings!$B$9,2),0) -> 4.51 | I6: =IF(A6="","",E6+F6-H6) -> 140.49 | J6: =IF(A6="","",MONTH(A6)) -> 1
H7: =IF(G7="Card",ROUND((E7+F7)*Settings!$B$8+Settings!$B$9,2),0) -> 0 | I7: =IF(A7="","",E7+F7-H7) | J7: =IF(A7="","",MONTH(A7))
H8: =IF(G8="Card",ROUND((E8+F8)*Settings!$B$8+Settings!$B$9,2),0) -> 0 | I8: =IF(A8="","",E8+F8-H8) | J8: =IF(A8="","",MONTH(A8))
H9: =IF(G9="Card",ROUND((E9+F9)*Settings!$B$8+Settings!$B$9,2),0) -> 0 | I9: =IF(A9="","",E9+F9-H9) | J9: =IF(A9="","",MONTH(A9))
H10: =IF(G10="Card",ROUND((E10+F10)*Settings!$B$8+Settings!$B$9,2),0) -> 0 | I10: =IF(A10="","",E10+F10-H10) | J10: =IF(A10="","",MONTH(A10))
H11: =IF(G11="Card",ROUND((E11+F11)*Settings!$B$8+Settings!$B$9,2),0) -> 0 | I11: =IF(A11="","",E11+F11-H11) | J11: =IF(A11="","",MONTH(A11))
H12: =IF(G12="Card",ROUND((E12+F12)*Settings!$B$8+Settings!$B$9,2),0) -> 0 | I12: =IF(A12="","",E12+F12-H12) | J12: =IF(A12="","",MONTH(A12))
H13: =IF(G13="Card",ROUND((E13+F13)*Settings!$B$8+Settings!$B$9,2),0) -> 0 | I13: =IF(A13="","",E13+F13-H13) | J13: =IF(A13="","",MONTH(A13))
H14: =IF(G14="Card",ROUND((E14+F14)*Settings!$B$8+Settings!$B$9,2),0) -> 0 | I14: =IF(A14="","",E14+F14-H14) | J14: =IF(A14="","",MONTH(A14))
H15: =IF(G15="Card",ROUND((E15+F15)*Settings!$B$8+Settings!$B$9,2),0) -> 0 | I15: =IF(A15="","",E15+F15-H15) | J15: =IF(A15="","",MONTH(A15))
H16: =IF(G16="Card",ROUND((E16+F16)*Settings!$B$8+Settings!$B$9,2),0) -> 0 | I16: =IF(A16="","",E16+F16-H16) | J16: =IF(A16="","",MONTH(A16))
H17: =IF(G17="Card",ROUND((E17+F17)*Settings!$B$8+Settings!$B$9,2),0) -> 0 | I17: =IF(A17="","",E17+F17-H17) | J17: =IF(A17="","",MONTH(A17))
H18: =IF(G18="Card",ROUND((E18+F18)*Settings!$B$8+Settings!$B$9,2),0) -> 0 | I18: =IF(A18="","",E18+F18-H18) | J18: =IF(A18="","",MONTH(A18))
... H605: =IF(G605="Card",ROUND((E605+F605)*Settings!$B$8+Settings!$B$9,2),0) -> 0 | I605: =IF(A605="","",E605+F605-H605) | J605: =IF(A605="","",MONTH(A605))

Sheet Expenses
A1: Expenses
A2: Everything the business pays for. Keep the receipts: your tax preparer will ask.
A3: Example on the first line: replace it with your first expense.
A5: DATE | B5: PAID TO | C5: WHAT | D5: CATEGORY | E5: AMOUNT | F5: PAID BY | G5: RECEIPT SAVED | H5: MONTH
A6: 46024 | B6: Skin supply co. | C6: Cleanser and masks (backbar) | D6: Backbar supplies | E6: 86.4 | F6: Card | G6: Yes | H6: =IF(A6="","",MONTH(A6)) -> 1
H7: =IF(A7="","",MONTH(A7))
H8: =IF(A8="","",MONTH(A8))
H9: =IF(A9="","",MONTH(A9))
H10: =IF(A10="","",MONTH(A10))
H11: =IF(A11="","",MONTH(A11))
H12: =IF(A12="","",MONTH(A12))
H13: =IF(A13="","",MONTH(A13))
H14: =IF(A14="","",MONTH(A14))
H15: =IF(A15="","",MONTH(A15))
H16: =IF(A16="","",MONTH(A16))
H17: =IF(A17="","",MONTH(A17))
H18: =IF(A18="","",MONTH(A18))
... H605: =IF(A605="","",MONTH(A605))

Sheet Products
A1: Products
A2: Your shelf: what each product earns, what's in stock and what to reorder.
A5: PRODUCT | B5: BRAND | C5: YOUR COST | D5: PRICE | E5: PROFIT EACH | F5: MARGIN | G5: IN STOCK | H5: REORDER AT | I5: REORDER? | J5: STOCK VALUE
A6: Gentle gel cleanser | B6: Your brand | C6: 14 | D6: 32 | E6: =IF(D6="","",D6-C6) -> 18 | F6: =IF(OR(D6="",D6=0),"",(D6-C6)/D6) -> 0.5625 | G6: 6 | H6: 3 | I6: =IF(OR(G6="",H6=""),"",IF(G6<=H6,"Reorder","")) | J6: =IF(OR(C6="",G6=""),"",C6*G6) -> 84
E7: =IF(D7="","",D7-C7) | F7: =IF(OR(D7="",D7=0),"",(D7-C7)/D7) | I7: =IF(OR(G7="",H7=""),"",IF(G7<=H7,"Reorder","")) | J7: =IF(OR(C7="",G7=""),"",C7*G7)
E8: =IF(D8="","",D8-C8) | F8: =IF(OR(D8="",D8=0),"",(D8-C8)/D8) | I8: =IF(OR(G8="",H8=""),"",IF(G8<=H8,"Reorder","")) | J8: =IF(OR(C8="",G8=""),"",C8*G8)
E9: =IF(D9="","",D9-C9) | F9: =IF(OR(D9="",D9=0),"",(D9-C9)/D9) | I9: =IF(OR(G9="",H9=""),"",IF(G9<=H9,"Reorder","")) | J9: =IF(OR(C9="",G9=""),"",C9*G9)
E10: =IF(D10="","",D10-C10) | F10: =IF(OR(D10="",D10=0),"",(D10-C10)/D10) | I10: =IF(OR(G10="",H10=""),"",IF(G10<=H10,"Reorder","")) | J10: =IF(OR(C10="",G10=""),"",C10*G10)
E11: =IF(D11="","",D11-C11) | F11: =IF(OR(D11="",D11=0),"",(D11-C11)/D11) | I11: =IF(OR(G11="",H11=""),"",IF(G11<=H11,"Reorder","")) | J11: =IF(OR(C11="",G11=""),"",C11*G11)
E12: =IF(D12="","",D12-C12) | F12: =IF(OR(D12="",D12=0),"",(D12-C12)/D12) | I12: =IF(OR(G12="",H12=""),"",IF(G12<=H12,"Reorder","")) | J12: =IF(OR(C12="",G12=""),"",C12*G12)
E13: =IF(D13="","",D13-C13) | F13: =IF(OR(D13="",D13=0),"",(D13-C13)/D13) | I13: =IF(OR(G13="",H13=""),"",IF(G13<=H13,"Reorder","")) | J13: =IF(OR(C13="",G13=""),"",C13*G13)
E14: =IF(D14="","",D14-C14) | F14: =IF(OR(D14="",D14=0),"",(D14-C14)/D14) | I14: =IF(OR(G14="",H14=""),"",IF(G14<=H14,"Reorder","")) | J14: =IF(OR(C14="",G14=""),"",C14*G14)
E15: =IF(D15="","",D15-C15) | F15: =IF(OR(D15="",D15=0),"",(D15-C15)/D15) | I15: =IF(OR(G15="",H15=""),"",IF(G15<=H15,"Reorder","")) | J15: =IF(OR(C15="",G15=""),"",C15*G15)
E16: =IF(D16="","",D16-C16) | F16: =IF(OR(D16="",D16=0),"",(D16-C16)/D16) | I16: =IF(OR(G16="",H16=""),"",IF(G16<=H16,"Reorder","")) | J16: =IF(OR(C16="",G16=""),"",C16*G16)
E17: =IF(D17="","",D17-C17) | F17: =IF(OR(D17="",D17=0),"",(D17-C17)/D17) | I17: =IF(OR(G17="",H17=""),"",IF(G17<=H17,"Reorder","")) | J17: =IF(OR(C17="",G17=""),"",C17*G17)
E18: =IF(D18="","",D18-C18) | F18: =IF(OR(D18="",D18=0),"",(D18-C18)/D18) | I18: =IF(OR(G18="",H18=""),"",IF(G18<=H18,"Reorder","")) | J18: =IF(OR(C18="",G18=""),"",C18*G18)
... E105: =IF(D105="","",D105-C105) | F105: =IF(OR(D105="",D105=0),"",(D105-C105)/D105) | I105: =IF(OR(G105="",H105=""),"",IF(G105<=H105,"Reorder","")) | J105: =IF(OR(C105="",G105=""),"",C105*G105)
A108: Total stock value | J108: =SUM(J6:J105) -> 84
A109: Aim for a margin of 50% or more on retail. Under 40%, check your price or your supplier.

Sheet Month by Month
A1: Month by Month
A2: Filled in from your Income and Expenses tabs. Nothing to type here.
B4: JAN | C4: FEB | D4: MAR | E4: APR | F4: MAY | G4: JUN | H4: JUL | I4: AUG | J4: SEP | K4: OCT | L4: NOV | M4: DEC | N4: YEAR
A5: INCOME
A6: =Settings!A12 -> Facials | B6: =SUMIFS(Income!$E$6:$E$605,Income!$D$6:$D$605,$A6,Income!$J$6:$J$605,1,Income!$A$6:$A$605,">="&DATE(Settings!$B$6,1,1),Income!$A$6:$A$605,"<="&DATE(Settings!$B$6,12,31)) -> 125 | C6: =SUMIFS(Income!$E$6:$E$605,Income!$D$6:$D$605,$A6,Income!$J$6:$J$605,2,Income!$A$6:$A$605,">="&DATE(Settings!$B$6,1,1),Income!$A$6:$A$605,"<="&DATE(Settings!$B$6,12,31)) -> 0 | D6: =SUMIFS(Income!$E$6:$E$605,Income!$D$6:$D$605,$A6,Income!$J$6:$J$605,3,Income!$A$6:$A$605,">="&DATE(Settings!$B$6,1,1),Income!$A$6:$A$605,"<="&DATE(Settings!$B$6,12,31)) -> 0 | E6: =SUMIFS(Income!$E$6:$E$605,Income!$D$6:$D$605,$A6,Income!$J$6:$J$605,4,Income!$A$6:$A$605,">="&DATE(Settings!$B$6,1,1),Income!$A$6:$A$605,"<="&DATE(Settings!$B$6,12,31)) -> 0 | F6: =SUMIFS(Income!$E$6:$E$605,Income!$D$6:$D$605,$A6,Income!$J$6:$J$605,5,Income!$A$6:$A$605,">="&DATE(Settings!$B$6,1,1),Income!$A$6:$A$605,"<="&DATE(Settings!$B$6,12,31)) -> 0 | G6: =SUMIFS(Income!$E$6:$E$605,Income!$D$6:$D$605,$A6,Income!$J$6:$J$605,6,Income!$A$6:$A$605,">="&DATE(Settings!$B$6,1,1),Income!$A$6:$A$605,"<="&DATE(Settings!$B$6,12,31)) -> 0 | H6: =SUMIFS(Income!$E$6:$E$605,Income!$D$6:$D$605,$A6,Income!$J$6:$J$605,7,Income!$A$6:$A$605,">="&DATE(Settings!$B$6,1,1),Income!$A$6:$A$605,"<="&DATE(Settings!$B$6,12,31)) -> 0 | I6: =SUMIFS(Income!$E$6:$E$605,Income!$D$6:$D$605,$A6,Income!$J$6:$J$605,8,Income!$A$6:$A$605,">="&DATE(Settings!$B$6,1,1),Income!$A$6:$A$605,"<="&DATE(Settings!$B$6,12,31)) -> 0 | J6: =SUMIFS(Income!$E$6:$E$605,Income!$D$6:$D$605,$A6,Income!$J$6:$J$605,9,Income!$A$6:$A$605,">="&DATE(Settings!$B$6,1,1),Income!$A$6:$A$605,"<="&DATE(Settings!$B$6,12,31)) -> 0 | K6: =SUMIFS(Income!$E$6:$E$605,Income!$D$6:$D$605,$A6,Income!$J$6:$J$605,10,Income!$A$6:$A$605,">="&DATE(Settings!$B$6,1,1),Income!$A$6:$A$605,"<="&DATE(Settings!$B$6,12,31)) -> 0 | L6: =SUMIFS(Income!$E$6:$E$605,Income!$D$6:$D$605,$A6,Income!$J$6:$J$605,11,Income!$A$6:$A$605,">="&DATE(Settings!$B$6,1,1),Income!$A$6:$A$605,"<="&DATE(Settings!$B$6,12,31)) -> 0 | M6: =SUMIFS(Income!$E$6:$E$605,Income!$D$6:$D$605,$A6,Income!$J$6:$J$605,12,Income!$A$6:$A$605,">="&DATE(Settings!$B$6,1,1),Income!$A$6:$A$605,"<="&DATE(Settings!$B$6,12,31)) -> 0 | N6: =SUM(B6:M6) -> 125
A7: =Settings!A13 -> Peels and advanced | B7: =SUMIFS(Income!$E$6:$E$605,Income!$D$6:$D$605,$A7,Income!$J$6:$J$605,1,Income!$A$6:$A$605,">="&DATE(Settings!$B$6,1,1),Income!$A$6:$A$605,"<="&DATE(Settings!$B$6,12,31)) -> 0 | C7: =SUMIFS(Income!$E$6:$E$605,Income!$D$6:$D$605,$A7,Income!$J$6:$J$605,2,Income!$A$6:$A$605,">="&DATE(Settings!$B$6,1,1),Income!$A$6:$A$605,"<="&DATE(Settings!$B$6,12,31)) -> 0 | D7: =SUMIFS(Income!$E$6:$E$605,Income!$D$6:$D$605,$A7,Income!$J$6:$J$605,3,Income!$A$6:$A$605,">="&DATE(Settings!$B$6,1,1),Income!$A$6:$A$605,"<="&DATE(Settings!$B$6,12,31)) -> 0 | E7: =SUMIFS(Income!$E$6:$E$605,Income!$D$6:$D$605,$A7,Income!$J$6:$J$605,4,Income!$A$6:$A$605,">="&DATE(Settings!$B$6,1,1),Income!$A$6:$A$605,"<="&DATE(Settings!$B$6,12,31)) -> 0 | F7: =SUMIFS(Income!$E$6:$E$605,Income!$D$6:$D$605,$A7,Income!$J$6:$J$605,5,Income!$A$6:$A$605,">="&DATE(Settings!$B$6,1,1),Income!$A$6:$A$605,"<="&DATE(Settings!$B$6,12,31)) -> 0 | G7: =SUMIFS(Income!$E$6:$E$605,Income!$D$6:$D$605,$A7,Income!$J$6:$J$605,6,Income!$A$6:$A$605,">="&DATE(Settings!$B$6,1,1),Income!$A$6:$A$605,"<="&DATE(Settings!$B$6,12,31)) -> 0 | H7: =SUMIFS(Income!$E$6:$E$605,Income!$D$6:$D$605,$A7,Income!$J$6:$J$605,7,Income!$A$6:$A$605,">="&DATE(Settings!$B$6,1,1),Income!$A$6:$A$605,"<="&DATE(Settings!$B$6,12,31)) -> 0 | I7: =SUMIFS(Income!$E$6:$E$605,Income!$D$6:$D$605,$A7,Income!$J$6:$J$605,8,Income!$A$6:$A$605,">="&DATE(Settings!$B$6,1,1),Income!$A$6:$A$605,"<="&DATE(Settings!$B$6,12,31)) -> 0 | J7: =SUMIFS(Income!$E$6:$E$605,Income!$D$6:$D$605,$A7,Income!$J$6:$J$605,9,Income!$A$6:$A$605,">="&DATE(Settings!$B$6,1,1),Income!$A$6:$A$605,"<="&DATE(Settings!$B$6,12,31)) -> 0 | K7: =SUMIFS(Income!$E$6:$E$605,Income!$D$6:$D$605,$A7,Income!$J$6:$J$605,10,Income!$A$6:$A$605,">="&DATE(Settings!$B$6,1,1),Income!$A$6:$A$605,"<="&DATE(Settings!$B$6,12,31)) -> 0 | L7: =SUMIFS(Income!$E$6:$E$605,Income!$D$6:$D$605,$A7,Income!$J$6:$J$605,11,Income!$A$6:$A$605,">="&DATE(Settings!$B$6,1,1),Income!$A$6:$A$605,"<="&DATE(Settings!$B$6,12,31)) -> 0 | M7: =SUMIFS(Income!$E$6:$E$605,Income!$D$6:$D$605,$A7,Income!$J$6:$J$605,12,Income!$A$6:$A$605,">="&DATE(Settings!$B$6,1,1),Income!$A$6:$A$605,"<="&DATE(Settings!$B$6,12,31)) -> 0 | N7: =SUM(B7:M7) -> 0
A8: =Settings!A14 -> Waxing | B8: =SUMIFS(Income!$E$6:$E$605,Income!$D$6:$D$605,$A8,Income!$J$6:$J$605,1,Income!$A$6:$A$605,">="&DATE(Settings!$B$6,1,1),Income!$A$6:$A$605,"<="&DATE(Settings!$B$6,12,31)) -> 0 | C8: =SUMIFS(Income!$E$6:$E$605,Income!$D$6:$D$605,$A8,Income!$J$6:$J$605,2,Income!$A$6:$A$605,">="&DATE(Settings!$B$6,1,1),Income!$A$6:$A$605,"<="&DATE(Settings!$B$6,12,31)) -> 0 | D8: =SUMIFS(Income!$E$6:$E$605,Income!$D$6:$D$605,$A8,Income!$J$6:$J$605,3,Income!$A$6:$A$605,">="&DATE(Settings!$B$6,1,1),Income!$A$6:$A$605,"<="&DATE(Settings!$B$6,12,31)) -> 0 | E8: =SUMIFS(Income!$E$6:$E$605,Income!$D$6:$D$605,$A8,Income!$J$6:$J$605,4,Income!$A$6:$A$605,">="&DATE(Settings!$B$6,1,1),Income!$A$6:$A$605,"<="&DATE(Settings!$B$6,12,31)) -> 0 | F8: =SUMIFS(Income!$E$6:$E$605,Income!$D$6:$D$605,$A8,Income!$J$6:$J$605,5,Income!$A$6:$A$605,">="&DATE(Settings!$B$6,1,1),Income!$A$6:$A$605,"<="&DATE(Settings!$B$6,12,31)) -> 0 | G8: =SUMIFS(Income!$E$6:$E$605,Income!$D$6:$D$605,$A8,Income!$J$6:$J$605,6,Income!$A$6:$A$605,">="&DATE(Settings!$B$6,1,1),Income!$A$6:$A$605,"<="&DATE(Settings!$B$6,12,31)) -> 0 | H8: =SUMIFS(Income!$E$6:$E$605,Income!$D$6:$D$605,$A8,Income!$J$6:$J$605,7,Income!$A$6:$A$605,">="&DATE(Settings!$B$6,1,1),Income!$A$6:$A$605,"<="&DATE(Settings!$B$6,12,31)) -> 0 | I8: =SUMIFS(Income!$E$6:$E$605,Income!$D$6:$D$605,$A8,Income!$J$6:$J$605,8,Income!$A$6:$A$605,">="&DATE(Settings!$B$6,1,1),Income!$A$6:$A$605,"<="&DATE(Settings!$B$6,12,31)) -> 0 | J8: =SUMIFS(Income!$E$6:$E$605,Income!$D$6:$D$605,$A8,Income!$J$6:$J$605,9,Income!$A$6:$A$605,">="&DATE(Settings!$B$6,1,1),Income!$A$6:$A$605,"<="&DATE(Settings!$B$6,12,31)) -> 0 | K8: =SUMIFS(Income!$E$6:$E$605,Income!$D$6:$D$605,$A8,Income!$J$6:$J$605,10,Income!$A$6:$A$605,">="&DATE(Settings!$B$6,1,1),Income!$A$6:$A$605,"<="&DATE(Settings!$B$6,12,31)) -> 0 | L8: =SUMIFS(Income!$E$6:$E$605,Income!$D$6:$D$605,$A8,Income!$J$6:$J$605,11,Income!$A$6:$A$605,">="&DATE(Settings!$B$6,1,1),Income!$A$6:$A$605,"<="&DATE(Settings!$B$6,12,31)) -> 0 | M8: =SUMIFS(Income!$E$6:$E$605,Income!$D$6:$D$605,$A8,Income!$J$6:$J$605,12,Income!$A$6:$A$605,">="&DATE(Settings!$B$6,1,1),Income!$A$6:$A$605,"<="&DATE(Settings!$B$6,12,31)) -> 0 | N8: =SUM(B8:M8) -> 0
A9: =Settings!A15 -> Lash and brow | B9: =SUMIFS(Income!$E$6:$E$605,Income!$D$6:$D$605,$A9,Income!$J$6:$J$605,1,Income!$A$6:$A$605,">="&DATE(Settings!$B$6,1,1),Income!$A$6:$A$605,"<="&DATE(Settings!$B$6,12,31)) -> 0 | C9: =SUMIFS(Income!$E$6:$E$605,Income!$D$6:$D$605,$A9,Income!$J$6:$J$605,2,Income!$A$6:$A$605,">="&DATE(Settings!$B$6,1,1),Income!$A$6:$A$605,"<="&DATE(Settings!$B$6,12,31)) -> 0 | D9: =SUMIFS(Income!$E$6:$E$605,Income!$D$6:$D$605,$A9,Income!$J$6:$J$605,3,Income!$A$6:$A$605,">="&DATE(Settings!$B$6,1,1),Income!$A$6:$A$605,"<="&DATE(Settings!$B$6,12,31)) -> 0 | E9: =SUMIFS(Income!$E$6:$E$605,Income!$D$6:$D$605,$A9,Income!$J$6:$J$605,4,Income!$A$6:$A$605,">="&DATE(Settings!$B$6,1,1),Income!$A$6:$A$605,"<="&DATE(Settings!$B$6,12,31)) -> 0 | F9: =SUMIFS(Income!$E$6:$E$605,Income!$D$6:$D$605,$A9,Income!$J$6:$J$605,5,Income!$A$6:$A$605,">="&DATE(Settings!$B$6,1,1),Income!$A$6:$A$605,"<="&DATE(Settings!$B$6,12,31)) -> 0 | G9: =SUMIFS(Income!$E$6:$E$605,Income!$D$6:$D$605,$A9,Income!$J$6:$J$605,6,Income!$A$6:$A$605,">="&DATE(Settings!$B$6,1,1),Income!$A$6:$A$605,"<="&DATE(Settings!$B$6,12,31)) -> 0 | H9: =SUMIFS(Income!$E$6:$E$605,Income!$D$6:$D$605,$A9,Income!$J$6:$J$605,7,Income!$A$6:$A$605,">="&DATE(Settings!$B$6,1,1),Income!$A$6:$A$605,"<="&DATE(Settings!$B$6,12,31)) -> 0 | I9: =SUMIFS(Income!$E$6:$E$605,Income!$D$6:$D$605,$A9,Income!$J$6:$J$605,8,Income!$A$6:$A$605,">="&DATE(Settings!$B$6,1,1),Income!$A$6:$A$605,"<="&DATE(Settings!$B$6,12,31)) -> 0 | J9: =SUMIFS(Income!$E$6:$E$605,Income!$D$6:$D$605,$A9,Income!$J$6:$J$605,9,Income!$A$6:$A$605,">="&DATE(Settings!$B$6,1,1),Income!$A$6:$A$605,"<="&DATE(Settings!$B$6,12,31)) -> 0 | K9: =SUMIFS(Income!$E$6:$E$605,Income!$D$6:$D$605,$A9,Income!$J$6:$J$605,10,Income!$A$6:$A$605,">="&DATE(Settings!$B$6,1,1),Income!$A$6:$A$605,"<="&DATE(Settings!$B$6,12,31)) -> 0 | L9: =SUMIFS(Income!$E$6:$E$605,Income!$D$6:$D$605,$A9,Income!$J$6:$J$605,11,Income!$A$6:$A$605,">="&DATE(Settings!$B$6,1,1),Income!$A$6:$A$605,"<="&DATE(Settings!$B$6,12,31)) -> 0 | M9: =SUMIFS(Income!$E$6:$E$605,Income!$D$6:$D$605,$A9,Income!$J$6:$J$605,12,Income!$A$6:$A$605,">="&DATE(Settings!$B$6,1,1),Income!$A$6:$A$605,"<="&DATE(Settings!$B$6,12,31)) -> 0 | N9: =SUM(B9:M9) -> 0
A10: =Settings!A16 -> Memberships | B10: =SUMIFS(Income!$E$6:$E$605,Income!$D$6:$D$605,$A10,Income!$J$6:$J$605,1,Income!$A$6:$A$605,">="&DATE(Settings!$B$6,1,1),Income!$A$6:$A$605,"<="&DATE(Settings!$B$6,12,31)) -> 0 | C10: =SUMIFS(Income!$E$6:$E$605,Income!$D$6:$D$605,$A10,Income!$J$6:$J$605,2,Income!$A$6:$A$605,">="&DATE(Settings!$B$6,1,1),Income!$A$6:$A$605,"<="&DATE(Settings!$B$6,12,31)) -> 0 | D10: =SUMIFS(Income!$E$6:$E$605,Income!$D$6:$D$605,$A10,Income!$J$6:$J$605,3,Income!$A$6:$A$605,">="&DATE(Settings!$B$6,1,1),Income!$A$6:$A$605,"<="&DATE(Settings!$B$6,12,31)) -> 0 | E10: =SUMIFS(Income!$E$6:$E$605,Income!$D$6:$D$605,$A10,Income!$J$6:$J$605,4,Income!$A$6:$A$605,">="&DATE(Settings!$B$6,1,1),Income!$A$6:$A$605,"<="&DATE(Settings!$B$6,12,31)) -> 0 | F10: =SUMIFS(Income!$E$6:$E$605,Income!$D$6:$D$605,$A10,Income!$J$6:$J$605,5,Income!$A$6:$A$605,">="&DATE(Settings!$B$6,1,1),Income!$A$6:$A$605,"<="&DATE(Settings!$B$6,12,31)) -> 0 | G10: =SUMIFS(Income!$E$6:$E$605,Income!$D$6:$D$605,$A10,Income!$J$6:$J$605,6,Income!$A$6:$A$605,">="&DATE(Settings!$B$6,1,1),Income!$A$6:$A$605,"<="&DATE(Settings!$B$6,12,31)) -> 0 | H10: =SUMIFS(Income!$E$6:$E$605,Income!$D$6:$D$605,$A10,Income!$J$6:$J$605,7,Income!$A$6:$A$605,">="&DATE(Settings!$B$6,1,1),Income!$A$6:$A$605,"<="&DATE(Settings!$B$6,12,31)) -> 0 | I10: =SUMIFS(Income!$E$6:$E$605,Income!$D$6:$D$605,$A10,Income!$J$6:$J$605,8,Income!$A$6:$A$605,">="&DATE(Settings!$B$6,1,1),Income!$A$6:$A$605,"<="&DATE(Settings!$B$6,12,31)) -> 0 | J10: =SUMIFS(Income!$E$6:$E$605,Income!$D$6:$D$605,$A10,Income!$J$6:$J$605,9,Income!$A$6:$A$605,">="&DATE(Settings!$B$6,1,1),Income!$A$6:$A$605,"<="&DATE(Settings!$B$6,12,31)) -> 0 | K10: =SUMIFS(Income!$E$6:$E$605,Income!$D$6:$D$605,$A10,Income!$J$6:$J$605,10,Income!$A$6:$A$605,">="&DATE(Settings!$B$6,1,1),Income!$A$6:$A$605,"<="&DATE(Settings!$B$6,12,31)) -> 0 | L10: =SUMIFS(Income!$E$6:$E$605,Income!$D$6:$D$605,$A10,Income!$J$6:$J$605,11,Income!$A$6:$A$605,">="&DATE(Settings!$B$6,1,1),Income!$A$6:$A$605,"<="&DATE(Settings!$B$6,12,31)) -> 0 | M10: =SUMIFS(Income!$E$6:$E$605,Income!$D$6:$D$605,$A10,Income!$J$6:$J$605,12,Income!$A$6:$A$605,">="&DATE(Settings!$B$6,1,1),Income!$A$6:$A$605,"<="&DATE(Settings!$B$6,12,31)) -> 0 | N10: =SUM(B10:M10) -> 0
A11: =Settings!A17 -> Products | B11: =SUMIFS(Income!$E$6:$E$605,Income!$D$6:$D$605,$A11,Income!$J$6:$J$605,1,Income!$A$6:$A$605,">="&DATE(Settings!$B$6,1,1),Income!$A$6:$A$605,"<="&DATE(Settings!$B$6,12,31)) -> 0 | C11: =SUMIFS(Income!$E$6:$E$605,Income!$D$6:$D$605,$A11,Income!$J$6:$J$605,2,Income!$A$6:$A$605,">="&DATE(Settings!$B$6,1,1),Income!$A$6:$A$605,"<="&DATE(Settings!$B$6,12,31)) -> 0 | D11: =SUMIFS(Income!$E$6:$E$605,Income!$D$6:$D$605,$A11,Income!$J$6:$J$605,3,Income!$A$6:$A$605,">="&DATE(Settings!$B$6,1,1),Income!$A$6:$A$605,"<="&DATE(Settings!$B$6,12,31)) -> 0 | E11: =SUMIFS(Income!$E$6:$E$605,Income!$D$6:$D$605,$A11,Income!$J$6:$J$605,4,Income!$A$6:$A$605,">="&DATE(Settings!$B$6,1,1),Income!$A$6:$A$605,"<="&DATE(Settings!$B$6,12,31)) -> 0 | F11: =SUMIFS(Income!$E$6:$E$605,Income!$D$6:$D$605,$A11,Income!$J$6:$J$605,5,Income!$A$6:$A$605,">="&DATE(Settings!$B$6,1,1),Income!$A$6:$A$605,"<="&DATE(Settings!$B$6,12,31)) -> 0 | G11: =SUMIFS(Income!$E$6:$E$605,Income!$D$6:$D$605,$A11,Income!$J$6:$J$605,6,Income!$A$6:$A$605,">="&DATE(Settings!$B$6,1,1),Income!$A$6:$A$605,"<="&DATE(Settings!$B$6,12,31)) -> 0 | H11: =SUMIFS(Income!$E$6:$E$605,Income!$D$6:$D$605,$A11,Income!$J$6:$J$605,7,Income!$A$6:$A$605,">="&DATE(Settings!$B$6,1,1),Income!$A$6:$A$605,"<="&DATE(Settings!$B$6,12,31)) -> 0 | I11: =SUMIFS(Income!$E$6:$E$605,Income!$D$6:$D$605,$A11,Income!$J$6:$J$605,8,Income!$A$6:$A$605,">="&DATE(Settings!$B$6,1,1),Income!$A$6:$A$605,"<="&DATE(Settings!$B$6,12,31)) -> 0 | J11: =SUMIFS(Income!$E$6:$E$605,Income!$D$6:$D$605,$A11,Income!$J$6:$J$605,9,Income!$A$6:$A$605,">="&DATE(Settings!$B$6,1,1),Income!$A$6:$A$605,"<="&DATE(Settings!$B$6,12,31)) -> 0 | K11: =SUMIFS(Income!$E$6:$E$605,Income!$D$6:$D$605,$A11,Income!$J$6:$J$605,10,Income!$A$6:$A$605,">="&DATE(Settings!$B$6,1,1),Income!$A$6:$A$605,"<="&DATE(Settings!$B$6,12,31)) -> 0 | L11: =SUMIFS(Income!$E$6:$E$605,Income!$D$6:$D$605,$A11,Income!$J$6:$J$605,11,Income!$A$6:$A$605,">="&DATE(Settings!$B$6,1,1),Income!$A$6:$A$605,"<="&DATE(Settings!$B$6,12,31)) -> 0 | M11: =SUMIFS(Income!$E$6:$E$605,Income!$D$6:$D$605,$A11,Income!$J$6:$J$605,12,Income!$A$6:$A$605,">="&DATE(Settings!$B$6,1,1),Income!$A$6:$A$605,"<="&DATE(Settings!$B$6,12,31)) -> 0 | N11: =SUM(B11:M11) -> 0
A12: =Settings!A18 -> Gift cards sold | B12: =SUMIFS(Income!$E$6:$E$605,Income!$D$6:$D$605,$A12,Income!$J$6:$J$605,1,Income!$A$6:$A$605,">="&DATE(Settings!$B$6,1,1),Income!$A$6:$A$605,"<="&DATE(Settings!$B$6,12,31)) -> 0 | C12: =SUMIFS(Income!$E$6:$E$605,Income!$D$6:$D$605,$A12,Income!$J$6:$J$605,2,Income!$A$6:$A$605,">="&DATE(Settings!$B$6,1,1),Income!$A$6:$A$605,"<="&DATE(Settings!$B$6,12,31)) -> 0 | D12: =SUMIFS(Income!$E$6:$E$605,Income!$D$6:$D$605,$A12,Income!$J$6:$J$605,3,Income!$A$6:$A$605,">="&DATE(Settings!$B$6,1,1),Income!$A$6:$A$605,"<="&DATE(Settings!$B$6,12,31)) -> 0 | E12: =SUMIFS(Income!$E$6:$E$605,Income!$D$6:$D$605,$A12,Income!$J$6:$J$605,4,Income!$A$6:$A$605,">="&DATE(Settings!$B$6,1,1),Income!$A$6:$A$605,"<="&DATE(Settings!$B$6,12,31)) -> 0 | F12: =SUMIFS(Income!$E$6:$E$605,Income!$D$6:$D$605,$A12,Income!$J$6:$J$605,5,Income!$A$6:$A$605,">="&DATE(Settings!$B$6,1,1),Income!$A$6:$A$605,"<="&DATE(Settings!$B$6,12,31)) -> 0 | G12: =SUMIFS(Income!$E$6:$E$605,Income!$D$6:$D$605,$A12,Income!$J$6:$J$605,6,Income!$A$6:$A$605,">="&DATE(Settings!$B$6,1,1),Income!$A$6:$A$605,"<="&DATE(Settings!$B$6,12,31)) -> 0 | H12: =SUMIFS(Income!$E$6:$E$605,Income!$D$6:$D$605,$A12,Income!$J$6:$J$605,7,Income!$A$6:$A$605,">="&DATE(Settings!$B$6,1,1),Income!$A$6:$A$605,"<="&DATE(Settings!$B$6,12,31)) -> 0 | I12: =SUMIFS(Income!$E$6:$E$605,Income!$D$6:$D$605,$A12,Income!$J$6:$J$605,8,Income!$A$6:$A$605,">="&DATE(Settings!$B$6,1,1),Income!$A$6:$A$605,"<="&DATE(Settings!$B$6,12,31)) -> 0 | J12: =SUMIFS(Income!$E$6:$E$605,Income!$D$6:$D$605,$A12,Income!$J$6:$J$605,9,Income!$A$6:$A$605,">="&DATE(Settings!$B$6,1,1),Income!$A$6:$A$605,"<="&DATE(Settings!$B$6,12,31)) -> 0 | K12: =SUMIFS(Income!$E$6:$E$605,Income!$D$6:$D$605,$A12,Income!$J$6:$J$605,10,Income!$A$6:$A$605,">="&DATE(Settings!$B$6,1,1),Income!$A$6:$A$605,"<="&DATE(Settings!$B$6,12,31)) -> 0 | L12: =SUMIFS(Income!$E$6:$E$605,Income!$D$6:$D$605,$A12,Income!$J$6:$J$605,11,Income!$A$6:$A$605,">="&DATE(Settings!$B$6,1,1),Income!$A$6:$A$605,"<="&DATE(Settings!$B$6,12,31)) -> 0 | M12: =SUMIFS(Income!$E$6:$E$605,Income!$D$6:$D$605,$A12,Income!$J$6:$J$605,12,Income!$A$6:$A$605,">="&DATE(Settings!$B$6,1,1),Income!$A$6:$A$605,"<="&DATE(Settings!$B$6,12,31)) -> 0 | N12: =SUM(B12:M12) -> 0
A13: =Settings!A19 -> Other services | B13: =SUMIFS(Income!$E$6:$E$605,Income!$D$6:$D$605,$A13,Income!$J$6:$J$605,1,Income!$A$6:$A$605,">="&DATE(Settings!$B$6,1,1),Income!$A$6:$A$605,"<="&DATE(Settings!$B$6,12,31)) -> 0 | C13: =SUMIFS(Income!$E$6:$E$605,Income!$D$6:$D$605,$A13,Income!$J$6:$J$605,2,Income!$A$6:$A$605,">="&DATE(Settings!$B$6,1,1),Income!$A$6:$A$605,"<="&DATE(Settings!$B$6,12,31)) -> 0 | D13: =SUMIFS(Income!$E$6:$E$605,Income!$D$6:$D$605,$A13,Income!$J$6:$J$605,3,Income!$A$6:$A$605,">="&DATE(Settings!$B$6,1,1),Income!$A$6:$A$605,"<="&DATE(Settings!$B$6,12,31)) -> 0 | E13: =SUMIFS(Income!$E$6:$E$605,Income!$D$6:$D$605,$A13,Income!$J$6:$J$605,4,Income!$A$6:$A$605,">="&DATE(Settings!$B$6,1,1),Income!$A$6:$A$605,"<="&DATE(Settings!$B$6,12,31)) -> 0 | F13: =SUMIFS(Income!$E$6:$E$605,Income!$D$6:$D$605,$A13,Income!$J$6:$J$605,5,Income!$A$6:$A$605,">="&DATE(Settings!$B$6,1,1),Income!$A$6:$A$605,"<="&DATE(Settings!$B$6,12,31)) -> 0 | G13: =SUMIFS(Income!$E$6:$E$605,Income!$D$6:$D$605,$A13,Income!$J$6:$J$605,6,Income!$A$6:$A$605,">="&DATE(Settings!$B$6,1,1),Income!$A$6:$A$605,"<="&DATE(Settings!$B$6,12,31)) -> 0 | H13: =SUMIFS(Income!$E$6:$E$605,Income!$D$6:$D$605,$A13,Income!$J$6:$J$605,7,Income!$A$6:$A$605,">="&DATE(Settings!$B$6,1,1),Income!$A$6:$A$605,"<="&DATE(Settings!$B$6,12,31)) -> 0 | I13: =SUMIFS(Income!$E$6:$E$605,Income!$D$6:$D$605,$A13,Income!$J$6:$J$605,8,Income!$A$6:$A$605,">="&DATE(Settings!$B$6,1,1),Income!$A$6:$A$605,"<="&DATE(Settings!$B$6,12,31)) -> 0 | J13: =SUMIFS(Income!$E$6:$E$605,Income!$D$6:$D$605,$A13,Income!$J$6:$J$605,9,Income!$A$6:$A$605,">="&DATE(Settings!$B$6,1,1),Income!$A$6:$A$605,"<="&DATE(Settings!$B$6,12,31)) -> 0 | K13: =SUMIFS(Income!$E$6:$E$605,Income!$D$6:$D$605,$A13,Income!$J$6:$J$605,10,Income!$A$6:$A$605,">="&DATE(Settings!$B$6,1,1),Income!$A$6:$A$605,"<="&DATE(Settings!$B$6,12,31)) -> 0 | L13: =SUMIFS(Income!$E$6:$E$605,Income!$D$6:$D$605,$A13,Income!$J$6:$J$605,11,Income!$A$6:$A$605,">="&DATE(Settings!$B$6,1,1),Income!$A$6:$A$605,"<="&DATE(Settings!$B$6,12,31)) -> 0 | M13: =SUMIFS(Income!$E$6:$E$605,Income!$D$6:$D$605,$A13,Income!$J$6:$J$605,12,Income!$A$6:$A$605,">="&DATE(Settings!$B$6,1,1),Income!$A$6:$A$605,"<="&DATE(Settings!$B$6,12,31)) -> 0 | N13: =SUM(B13:M13) -> 0
A14: Tips | B14: =SUMIFS(Income!$F$6:$F$605,Income!$J$6:$J$605,1,Income!$A$6:$A$605,">="&DATE(Settings!$B$6,1,1),Income!$A$6:$A$605,"<="&DATE(Settings!$B$6,12,31)) -> 20 | C14: =SUMIFS(Income!$F$6:$F$605,Income!$J$6:$J$605,2,Income!$A$6:$A$605,">="&DATE(Settings!$B$6,1,1),Income!$A$6:$A$605,"<="&DATE(Settings!$B$6,12,31)) -> 0 | D14: =SUMIFS(Income!$F$6:$F$605,Income!$J$6:$J$605,3,Income!$A$6:$A$605,">="&DATE(Settings!$B$6,1,1),Income!$A$6:$A$605,"<="&DATE(Settings!$B$6,12,31)) -> 0 | E14: =SUMIFS(Income!$F$6:$F$605,Income!$J$6:$J$605,4,Income!$A$6:$A$605,">="&DATE(Settings!$B$6,1,1),Income!$A$6:$A$605,"<="&DATE(Settings!$B$6,12,31)) -> 0 | F14: =SUMIFS(Income!$F$6:$F$605,Income!$J$6:$J$605,5,Income!$A$6:$A$605,">="&DATE(Settings!$B$6,1,1),Income!$A$6:$A$605,"<="&DATE(Settings!$B$6,12,31)) -> 0 | G14: =SUMIFS(Income!$F$6:$F$605,Income!$J$6:$J$605,6,Income!$A$6:$A$605,">="&DATE(Settings!$B$6,1,1),Income!$A$6:$A$605,"<="&DATE(Settings!$B$6,12,31)) -> 0 | H14: =SUMIFS(Income!$F$6:$F$605,Income!$J$6:$J$605,7,Income!$A$6:$A$605,">="&DATE(Settings!$B$6,1,1),Income!$A$6:$A$605,"<="&DATE(Settings!$B$6,12,31)) -> 0 | I14: =SUMIFS(Income!$F$6:$F$605,Income!$J$6:$J$605,8,Income!$A$6:$A$605,">="&DATE(Settings!$B$6,1,1),Income!$A$6:$A$605,"<="&DATE(Settings!$B$6,12,31)) -> 0 | J14: =SUMIFS(Income!$F$6:$F$605,Income!$J$6:$J$605,9,Income!$A$6:$A$605,">="&DATE(Settings!$B$6,1,1),Income!$A$6:$A$605,"<="&DATE(Settings!$B$6,12,31)) -> 0 | K14: =SUMIFS(Income!$F$6:$F$605,Income!$J$6:$J$605,10,Income!$A$6:$A$605,">="&DATE(Settings!$B$6,1,1),Income!$A$6:$A$605,"<="&DATE(Settings!$B$6,12,31)) -> 0 | L14: =SUMIFS(Income!$F$6:$F$605,Income!$J$6:$J$605,11,Income!$A$6:$A$605,">="&DATE(Settings!$B$6,1,1),Income!$A$6:$A$605,"<="&DATE(Settings!$B$6,12,31)) -> 0 | M14: =SUMIFS(Income!$F$6:$F$605,Income!$J$6:$J$605,12,Income!$A$6:$A$605,">="&DATE(Settings!$B$6,1,1),Income!$A$6:$A$605,"<="&DATE(Settings!$B$6,12,31)) -> 0 | N14: =SUM(B14:M14) -> 20
A15: Total income | B15: =SUM(B6:B14) -> 145 | C15: =SUM(C6:C14) -> 0 | D15: =SUM(D6:D14) -> 0 | E15: =SUM(E6:E14) -> 0 | F15: =SUM(F6:F14) -> 0 | G15: =SUM(G6:G14) -> 0 | H15: =SUM(H6:H14) -> 0 | I15: =SUM(I6:I14) -> 0 | ... N15: =SUM(N6:N14) -> 145
A17: EXPENSES
A18: Card fees | B18: =SUMIFS(Income!$H$6:$H$605,Income!$J$6:$J$605,1,Income!$A$6:$A$605,">="&DATE(Settings!$B$6,1,1),Income!$A$6:$A$605,"<="&DATE(Settings!$B$6,12,31)) -> 4.51 | C18: =SUMIFS(Income!$H$6:$H$605,Income!$J$6:$J$605,2,Income!$A$6:$A$605,">="&DATE(Settings!$B$6,1,1),Income!$A$6:$A$605,"<="&DATE(Settings!$B$6,12,31)) -> 0 | D18: =SUMIFS(Income!$H$6:$H$605,Income!$J$6:$J$605,3,Income!$A$6:$A$605,">="&DATE(Settings!$B$6,1,1),Income!$A$6:$A$605,"<="&DATE(Settings!$B$6,12,31)) -> 0 | E18: =SUMIFS(Income!$H$6:$H$605,Income!$J$6:$J$605,4,Income!$A$6:$A$605,">="&DATE(Settings!$B$6,1,1),Income!$A$6:$A$605,"<="&DATE(Settings!$B$6,12,31)) -> 0 | F18: =SUMIFS(Income!$H$6:$H$605,Income!$J$6:$J$605,5,Income!$A$6:$A$605,">="&DATE(Settings!$B$6,1,1),Income!$A$6:$A$605,"<="&DATE(Settings!$B$6,12,31)) -> 0 | G18: =SUMIFS(Income!$H$6:$H$605,Income!$J$6:$J$605,6,Income!$A$6:$A$605,">="&DATE(Settings!$B$6,1,1),Income!$A$6:$A$605,"<="&DATE(Settings!$B$6,12,31)) -> 0 | H18: =SUMIFS(Income!$H$6:$H$605,Income!$J$6:$J$605,7,Income!$A$6:$A$605,">="&DATE(Settings!$B$6,1,1),Income!$A$6:$A$605,"<="&DATE(Settings!$B$6,12,31)) -> 0 | I18: =SUMIFS(Income!$H$6:$H$605,Income!$J$6:$J$605,8,Income!$A$6:$A$605,">="&DATE(Settings!$B$6,1,1),Income!$A$6:$A$605,"<="&DATE(Settings!$B$6,12,31)) -> 0 | J18: =SUMIFS(Income!$H$6:$H$605,Income!$J$6:$J$605,9,Income!$A$6:$A$605,">="&DATE(Settings!$B$6,1,1),Income!$A$6:$A$605,"<="&DATE(Settings!$B$6,12,31)) -> 0 | K18: =SUMIFS(Income!$H$6:$H$605,Income!$J$6:$J$605,10,Income!$A$6:$A$605,">="&DATE(Settings!$B$6,1,1),Income!$A$6:$A$605,"<="&DATE(Settings!$B$6,12,31)) -> 0 | L18: =SUMIFS(Income!$H$6:$H$605,Income!$J$6:$J$605,11,Income!$A$6:$A$605,">="&DATE(Settings!$B$6,1,1),Income!$A$6:$A$605,"<="&DATE(Settings!$B$6,12,31)) -> 0 | M18: =SUMIFS(Income!$H$6:$H$605,Income!$J$6:$J$605,12,Income!$A$6:$A$605,">="&DATE(Settings!$B$6,1,1),Income!$A$6:$A$605,"<="&DATE(Settings!$B$6,12,31)) -> 0 | N18: =SUM(B18:M18) -> 4.51
A19: =Settings!D12 -> Rent and utilities | B19: =SUMIFS(Expenses!$E$6:$E$605,Expenses!$D$6:$D$605,$A19,Expenses!$H$6:$H$605,1,Expenses!$A$6:$A$605,">="&DATE(Settings!$B$6,1,1),Expenses!$A$6:$A$605,"<="&DATE(Settings!$B$6,12,31)) -> 0 | C19: =SUMIFS(Expenses!$E$6:$E$605,Expenses!$D$6:$D$605,$A19,Expenses!$H$6:$H$605,2,Expenses!$A$6:$A$605,">="&DATE(Settings!$B$6,1,1),Expenses!$A$6:$A$605,"<="&DATE(Settings!$B$6,12,31)) -> 0 | D19: =SUMIFS(Expenses!$E$6:$E$605,Expenses!$D$6:$D$605,$A19,Expenses!$H$6:$H$605,3,Expenses!$A$6:$A$605,">="&DATE(Settings!$B$6,1,1),Expenses!$A$6:$A$605,"<="&DATE(Settings!$B$6,12,31)) -> 0 | E19: =SUMIFS(Expenses!$E$6:$E$605,Expenses!$D$6:$D$605,$A19,Expenses!$H$6:$H$605,4,Expenses!$A$6:$A$605,">="&DATE(Settings!$B$6,1,1),Expenses!$A$6:$A$605,"<="&DATE(Settings!$B$6,12,31)) -> 0 | F19: =SUMIFS(Expenses!$E$6:$E$605,Expenses!$D$6:$D$605,$A19,Expenses!$H$6:$H$605,5,Expenses!$A$6:$A$605,">="&DATE(Settings!$B$6,1,1),Expenses!$A$6:$A$605,"<="&DATE(Settings!$B$6,12,31)) -> 0 | G19: =SUMIFS(Expenses!$E$6:$E$605,Expenses!$D$6:$D$605,$A19,Expenses!$H$6:$H$605,6,Expenses!$A$6:$A$605,">="&DATE(Settings!$B$6,1,1),Expenses!$A$6:$A$605,"<="&DATE(Settings!$B$6,12,31)) -> 0 | H19: =SUMIFS(Expenses!$E$6:$E$605,Expenses!$D$6:$D$605,$A19,Expenses!$H$6:$H$605,7,Expenses!$A$6:$A$605,">="&DATE(Settings!$B$6,1,1),Expenses!$A$6:$A$605,"<="&DATE(Settings!$B$6,12,31)) -> 0 | I19: =SUMIFS(Expenses!$E$6:$E$605,Expenses!$D$6:$D$605,$A19,Expenses!$H$6:$H$605,8,Expenses!$A$6:$A$605,">="&DATE(Settings!$B$6,1,1),Expenses!$A$6:$A$605,"<="&DATE(Settings!$B$6,12,31)) -> 0 | J19: =SUMIFS(Expenses!$E$6:$E$605,Expenses!$D$6:$D$605,$A19,Expenses!$H$6:$H$605,9,Expenses!$A$6:$A$605,">="&DATE(Settings!$B$6,1,1),Expenses!$A$6:$A$605,"<="&DATE(Settings!$B$6,12,31)) -> 0 | K19: =SUMIFS(Expenses!$E$6:$E$605,Expenses!$D$6:$D$605,$A19,Expenses!$H$6:$H$605,10,Expenses!$A$6:$A$605,">="&DATE(Settings!$B$6,1,1),Expenses!$A$6:$A$605,"<="&DATE(Settings!$B$6,12,31)) -> 0 | L19: =SUMIFS(Expenses!$E$6:$E$605,Expenses!$D$6:$D$605,$A19,Expenses!$H$6:$H$605,11,Expenses!$A$6:$A$605,">="&DATE(Settings!$B$6,1,1),Expenses!$A$6:$A$605,"<="&DATE(Settings!$B$6,12,31)) -> 0 | M19: =SUMIFS(Expenses!$E$6:$E$605,Expenses!$D$6:$D$605,$A19,Expenses!$H$6:$H$605,12,Expenses!$A$6:$A$605,">="&DATE(Settings!$B$6,1,1),Expenses!$A$6:$A$605,"<="&DATE(Settings!$B$6,12,31)) -> 0 | N19: =SUM(B19:M19) -> 0
A20: =Settings!D13 -> Backbar supplies | B20: =SUMIFS(Expenses!$E$6:$E$605,Expenses!$D$6:$D$605,$A20,Expenses!$H$6:$H$605,1,Expenses!$A$6:$A$605,">="&DATE(Settings!$B$6,1,1),Expenses!$A$6:$A$605,"<="&DATE(Settings!$B$6,12,31)) -> 86.4 | C20: =SUMIFS(Expenses!$E$6:$E$605,Expenses!$D$6:$D$605,$A20,Expenses!$H$6:$H$605,2,Expenses!$A$6:$A$605,">="&DATE(Settings!$B$6,1,1),Expenses!$A$6:$A$605,"<="&DATE(Settings!$B$6,12,31)) -> 0 | D20: =SUMIFS(Expenses!$E$6:$E$605,Expenses!$D$6:$D$605,$A20,Expenses!$H$6:$H$605,3,Expenses!$A$6:$A$605,">="&DATE(Settings!$B$6,1,1),Expenses!$A$6:$A$605,"<="&DATE(Settings!$B$6,12,31)) -> 0 | E20: =SUMIFS(Expenses!$E$6:$E$605,Expenses!$D$6:$D$605,$A20,Expenses!$H$6:$H$605,4,Expenses!$A$6:$A$605,">="&DATE(Settings!$B$6,1,1),Expenses!$A$6:$A$605,"<="&DATE(Settings!$B$6,12,31)) -> 0 | F20: =SUMIFS(Expenses!$E$6:$E$605,Expenses!$D$6:$D$605,$A20,Expenses!$H$6:$H$605,5,Expenses!$A$6:$A$605,">="&DATE(Settings!$B$6,1,1),Expenses!$A$6:$A$605,"<="&DATE(Settings!$B$6,12,31)) -> 0 | G20: =SUMIFS(Expenses!$E$6:$E$605,Expenses!$D$6:$D$605,$A20,Expenses!$H$6:$H$605,6,Expenses!$A$6:$A$605,">="&DATE(Settings!$B$6,1,1),Expenses!$A$6:$A$605,"<="&DATE(Settings!$B$6,12,31)) -> 0 | H20: =SUMIFS(Expenses!$E$6:$E$605,Expenses!$D$6:$D$605,$A20,Expenses!$H$6:$H$605,7,Expenses!$A$6:$A$605,">="&DATE(Settings!$B$6,1,1),Expenses!$A$6:$A$605,"<="&DATE(Settings!$B$6,12,31)) -> 0 | I20: =SUMIFS(Expenses!$E$6:$E$605,Expenses!$D$6:$D$605,$A20,Expenses!$H$6:$H$605,8,Expenses!$A$6:$A$605,">="&DATE(Settings!$B$6,1,1),Expenses!$A$6:$A$605,"<="&DATE(Settings!$B$6,12,31)) -> 0 | J20: =SUMIFS(Expenses!$E$6:$E$605,Expenses!$D$6:$D$605,$A20,Expenses!$H$6:$H$605,9,Expenses!$A$6:$A$605,">="&DATE(Settings!$B$6,1,1),Expenses!$A$6:$A$605,"<="&DATE(Settings!$B$6,12,31)) -> 0 | K20: =SUMIFS(Expenses!$E$6:$E$605,Expenses!$D$6:$D$605,$A20,Expenses!$H$6:$H$605,10,Expenses!$A$6:$A$605,">="&DATE(Settings!$B$6,1,1),Expenses!$A$6:$A$605,"<="&DATE(Settings!$B$6,12,31)) -> 0 | L20: =SUMIFS(Expenses!$E$6:$E$605,Expenses!$D$6:$D$605,$A20,Expenses!$H$6:$H$605,11,Expenses!$A$6:$A$605,">="&DATE(Settings!$B$6,1,1),Expenses!$A$6:$A$605,"<="&DATE(Settings!$B$6,12,31)) -> 0 | M20: =SUMIFS(Expenses!$E$6:$E$605,Expenses!$D$6:$D$605,$A20,Expenses!$H$6:$H$605,12,Expenses!$A$6:$A$605,">="&DATE(Settings!$B$6,1,1),Expenses!$A$6:$A$605,"<="&DATE(Settings!$B$6,12,31)) -> 0 | N20: =SUM(B20:M20) -> 86.4
A21: =Settings!D14 -> Retail inventory | B21: =SUMIFS(Expenses!$E$6:$E$605,Expenses!$D$6:$D$605,$A21,Expenses!$H$6:$H$605,1,Expenses!$A$6:$A$605,">="&DATE(Settings!$B$6,1,1),Expenses!$A$6:$A$605,"<="&DATE(Settings!$B$6,12,31)) -> 0 | C21: =SUMIFS(Expenses!$E$6:$E$605,Expenses!$D$6:$D$605,$A21,Expenses!$H$6:$H$605,2,Expenses!$A$6:$A$605,">="&DATE(Settings!$B$6,1,1),Expenses!$A$6:$A$605,"<="&DATE(Settings!$B$6,12,31)) -> 0 | D21: =SUMIFS(Expenses!$E$6:$E$605,Expenses!$D$6:$D$605,$A21,Expenses!$H$6:$H$605,3,Expenses!$A$6:$A$605,">="&DATE(Settings!$B$6,1,1),Expenses!$A$6:$A$605,"<="&DATE(Settings!$B$6,12,31)) -> 0 | E21: =SUMIFS(Expenses!$E$6:$E$605,Expenses!$D$6:$D$605,$A21,Expenses!$H$6:$H$605,4,Expenses!$A$6:$A$605,">="&DATE(Settings!$B$6,1,1),Expenses!$A$6:$A$605,"<="&DATE(Settings!$B$6,12,31)) -> 0 | F21: =SUMIFS(Expenses!$E$6:$E$605,Expenses!$D$6:$D$605,$A21,Expenses!$H$6:$H$605,5,Expenses!$A$6:$A$605,">="&DATE(Settings!$B$6,1,1),Expenses!$A$6:$A$605,"<="&DATE(Settings!$B$6,12,31)) -> 0 | G21: =SUMIFS(Expenses!$E$6:$E$605,Expenses!$D$6:$D$605,$A21,Expenses!$H$6:$H$605,6,Expenses!$A$6:$A$605,">="&DATE(Settings!$B$6,1,1),Expenses!$A$6:$A$605,"<="&DATE(Settings!$B$6,12,31)) -> 0 | H21: =SUMIFS(Expenses!$E$6:$E$605,Expenses!$D$6:$D$605,$A21,Expenses!$H$6:$H$605,7,Expenses!$A$6:$A$605,">="&DATE(Settings!$B$6,1,1),Expenses!$A$6:$A$605,"<="&DATE(Settings!$B$6,12,31)) -> 0 | I21: =SUMIFS(Expenses!$E$6:$E$605,Expenses!$D$6:$D$605,$A21,Expenses!$H$6:$H$605,8,Expenses!$A$6:$A$605,">="&DATE(Settings!$B$6,1,1),Expenses!$A$6:$A$605,"<="&DATE(Settings!$B$6,12,31)) -> 0 | J21: =SUMIFS(Expenses!$E$6:$E$605,Expenses!$D$6:$D$605,$A21,Expenses!$H$6:$H$605,9,Expenses!$A$6:$A$605,">="&DATE(Settings!$B$6,1,1),Expenses!$A$6:$A$605,"<="&DATE(Settings!$B$6,12,31)) -> 0 | K21: =SUMIFS(Expenses!$E$6:$E$605,Expenses!$D$6:$D$605,$A21,Expenses!$H$6:$H$605,10,Expenses!$A$6:$A$605,">="&DATE(Settings!$B$6,1,1),Expenses!$A$6:$A$605,"<="&DATE(Settings!$B$6,12,31)) -> 0 | L21: =SUMIFS(Expenses!$E$6:$E$605,Expenses!$D$6:$D$605,$A21,Expenses!$H$6:$H$605,11,Expenses!$A$6:$A$605,">="&DATE(Settings!$B$6,1,1),Expenses!$A$6:$A$605,"<="&DATE(Settings!$B$6,12,31)) -> 0 | M21: =SUMIFS(Expenses!$E$6:$E$605,Expenses!$D$6:$D$605,$A21,Expenses!$H$6:$H$605,12,Expenses!$A$6:$A$605,">="&DATE(Settings!$B$6,1,1),Expenses!$A$6:$A$605,"<="&DATE(Settings!$B$6,12,31)) -> 0 | N21: =SUM(B21:M21) -> 0
A22: =Settings!D15 -> Equipment | B22: =SUMIFS(Expenses!$E$6:$E$605,Expenses!$D$6:$D$605,$A22,Expenses!$H$6:$H$605,1,Expenses!$A$6:$A$605,">="&DATE(Settings!$B$6,1,1),Expenses!$A$6:$A$605,"<="&DATE(Settings!$B$6,12,31)) -> 0 | C22: =SUMIFS(Expenses!$E$6:$E$605,Expenses!$D$6:$D$605,$A22,Expenses!$H$6:$H$605,2,Expenses!$A$6:$A$605,">="&DATE(Settings!$B$6,1,1),Expenses!$A$6:$A$605,"<="&DATE(Settings!$B$6,12,31)) -> 0 | D22: =SUMIFS(Expenses!$E$6:$E$605,Expenses!$D$6:$D$605,$A22,Expenses!$H$6:$H$605,3,Expenses!$A$6:$A$605,">="&DATE(Settings!$B$6,1,1),Expenses!$A$6:$A$605,"<="&DATE(Settings!$B$6,12,31)) -> 0 | E22: =SUMIFS(Expenses!$E$6:$E$605,Expenses!$D$6:$D$605,$A22,Expenses!$H$6:$H$605,4,Expenses!$A$6:$A$605,">="&DATE(Settings!$B$6,1,1),Expenses!$A$6:$A$605,"<="&DATE(Settings!$B$6,12,31)) -> 0 | F22: =SUMIFS(Expenses!$E$6:$E$605,Expenses!$D$6:$D$605,$A22,Expenses!$H$6:$H$605,5,Expenses!$A$6:$A$605,">="&DATE(Settings!$B$6,1,1),Expenses!$A$6:$A$605,"<="&DATE(Settings!$B$6,12,31)) -> 0 | G22: =SUMIFS(Expenses!$E$6:$E$605,Expenses!$D$6:$D$605,$A22,Expenses!$H$6:$H$605,6,Expenses!$A$6:$A$605,">="&DATE(Settings!$B$6,1,1),Expenses!$A$6:$A$605,"<="&DATE(Settings!$B$6,12,31)) -> 0 | H22: =SUMIFS(Expenses!$E$6:$E$605,Expenses!$D$6:$D$605,$A22,Expenses!$H$6:$H$605,7,Expenses!$A$6:$A$605,">="&DATE(Settings!$B$6,1,1),Expenses!$A$6:$A$605,"<="&DATE(Settings!$B$6,12,31)) -> 0 | I22: =SUMIFS(Expenses!$E$6:$E$605,Expenses!$D$6:$D$605,$A22,Expenses!$H$6:$H$605,8,Expenses!$A$6:$A$605,">="&DATE(Settings!$B$6,1,1),Expenses!$A$6:$A$605,"<="&DATE(Settings!$B$6,12,31)) -> 0 | J22: =SUMIFS(Expenses!$E$6:$E$605,Expenses!$D$6:$D$605,$A22,Expenses!$H$6:$H$605,9,Expenses!$A$6:$A$605,">="&DATE(Settings!$B$6,1,1),Expenses!$A$6:$A$605,"<="&DATE(Settings!$B$6,12,31)) -> 0 | K22: =SUMIFS(Expenses!$E$6:$E$605,Expenses!$D$6:$D$605,$A22,Expenses!$H$6:$H$605,10,Expenses!$A$6:$A$605,">="&DATE(Settings!$B$6,1,1),Expenses!$A$6:$A$605,"<="&DATE(Settings!$B$6,12,31)) -> 0 | L22: =SUMIFS(Expenses!$E$6:$E$605,Expenses!$D$6:$D$605,$A22,Expenses!$H$6:$H$605,11,Expenses!$A$6:$A$605,">="&DATE(Settings!$B$6,1,1),Expenses!$A$6:$A$605,"<="&DATE(Settings!$B$6,12,31)) -> 0 | M22: =SUMIFS(Expenses!$E$6:$E$605,Expenses!$D$6:$D$605,$A22,Expenses!$H$6:$H$605,12,Expenses!$A$6:$A$605,">="&DATE(Settings!$B$6,1,1),Expenses!$A$6:$A$605,"<="&DATE(Settings!$B$6,12,31)) -> 0 | N22: =SUM(B22:M22) -> 0
A23: =Settings!D16 -> Insurance and licenses | B23: =SUMIFS(Expenses!$E$6:$E$605,Expenses!$D$6:$D$605,$A23,Expenses!$H$6:$H$605,1,Expenses!$A$6:$A$605,">="&DATE(Settings!$B$6,1,1),Expenses!$A$6:$A$605,"<="&DATE(Settings!$B$6,12,31)) -> 0 | C23: =SUMIFS(Expenses!$E$6:$E$605,Expenses!$D$6:$D$605,$A23,Expenses!$H$6:$H$605,2,Expenses!$A$6:$A$605,">="&DATE(Settings!$B$6,1,1),Expenses!$A$6:$A$605,"<="&DATE(Settings!$B$6,12,31)) -> 0 | D23: =SUMIFS(Expenses!$E$6:$E$605,Expenses!$D$6:$D$605,$A23,Expenses!$H$6:$H$605,3,Expenses!$A$6:$A$605,">="&DATE(Settings!$B$6,1,1),Expenses!$A$6:$A$605,"<="&DATE(Settings!$B$6,12,31)) -> 0 | E23: =SUMIFS(Expenses!$E$6:$E$605,Expenses!$D$6:$D$605,$A23,Expenses!$H$6:$H$605,4,Expenses!$A$6:$A$605,">="&DATE(Settings!$B$6,1,1),Expenses!$A$6:$A$605,"<="&DATE(Settings!$B$6,12,31)) -> 0 | F23: =SUMIFS(Expenses!$E$6:$E$605,Expenses!$D$6:$D$605,$A23,Expenses!$H$6:$H$605,5,Expenses!$A$6:$A$605,">="&DATE(Settings!$B$6,1,1),Expenses!$A$6:$A$605,"<="&DATE(Settings!$B$6,12,31)) -> 0 | G23: =SUMIFS(Expenses!$E$6:$E$605,Expenses!$D$6:$D$605,$A23,Expenses!$H$6:$H$605,6,Expenses!$A$6:$A$605,">="&DATE(Settings!$B$6,1,1),Expenses!$A$6:$A$605,"<="&DATE(Settings!$B$6,12,31)) -> 0 | H23: =SUMIFS(Expenses!$E$6:$E$605,Expenses!$D$6:$D$605,$A23,Expenses!$H$6:$H$605,7,Expenses!$A$6:$A$605,">="&DATE(Settings!$B$6,1,1),Expenses!$A$6:$A$605,"<="&DATE(Settings!$B$6,12,31)) -> 0 | I23: =SUMIFS(Expenses!$E$6:$E$605,Expenses!$D$6:$D$605,$A23,Expenses!$H$6:$H$605,8,Expenses!$A$6:$A$605,">="&DATE(Settings!$B$6,1,1),Expenses!$A$6:$A$605,"<="&DATE(Settings!$B$6,12,31)) -> 0 | J23: =SUMIFS(Expenses!$E$6:$E$605,Expenses!$D$6:$D$605,$A23,Expenses!$H$6:$H$605,9,Expenses!$A$6:$A$605,">="&DATE(Settings!$B$6,1,1),Expenses!$A$6:$A$605,"<="&DATE(Settings!$B$6,12,31)) -> 0 | K23: =SUMIFS(Expenses!$E$6:$E$605,Expenses!$D$6:$D$605,$A23,Expenses!$H$6:$H$605,10,Expenses!$A$6:$A$605,">="&DATE(Settings!$B$6,1,1),Expenses!$A$6:$A$605,"<="&DATE(Settings!$B$6,12,31)) -> 0 | L23: =SUMIFS(Expenses!$E$6:$E$605,Expenses!$D$6:$D$605,$A23,Expenses!$H$6:$H$605,11,Expenses!$A$6:$A$605,">="&DATE(Settings!$B$6,1,1),Expenses!$A$6:$A$605,"<="&DATE(Settings!$B$6,12,31)) -> 0 | M23: =SUMIFS(Expenses!$E$6:$E$605,Expenses!$D$6:$D$605,$A23,Expenses!$H$6:$H$605,12,Expenses!$A$6:$A$605,">="&DATE(Settings!$B$6,1,1),Expenses!$A$6:$A$605,"<="&DATE(Settings!$B$6,12,31)) -> 0 | N23: =SUM(B23:M23) -> 0
A24: =Settings!D17 -> Software and booking | B24: =SUMIFS(Expenses!$E$6:$E$605,Expenses!$D$6:$D$605,$A24,Expenses!$H$6:$H$605,1,Expenses!$A$6:$A$605,">="&DATE(Settings!$B$6,1,1),Expenses!$A$6:$A$605,"<="&DATE(Settings!$B$6,12,31)) -> 0 | C24: =SUMIFS(Expenses!$E$6:$E$605,Expenses!$D$6:$D$605,$A24,Expenses!$H$6:$H$605,2,Expenses!$A$6:$A$605,">="&DATE(Settings!$B$6,1,1),Expenses!$A$6:$A$605,"<="&DATE(Settings!$B$6,12,31)) -> 0 | D24: =SUMIFS(Expenses!$E$6:$E$605,Expenses!$D$6:$D$605,$A24,Expenses!$H$6:$H$605,3,Expenses!$A$6:$A$605,">="&DATE(Settings!$B$6,1,1),Expenses!$A$6:$A$605,"<="&DATE(Settings!$B$6,12,31)) -> 0 | E24: =SUMIFS(Expenses!$E$6:$E$605,Expenses!$D$6:$D$605,$A24,Expenses!$H$6:$H$605,4,Expenses!$A$6:$A$605,">="&DATE(Settings!$B$6,1,1),Expenses!$A$6:$A$605,"<="&DATE(Settings!$B$6,12,31)) -> 0 | F24: =SUMIFS(Expenses!$E$6:$E$605,Expenses!$D$6:$D$605,$A24,Expenses!$H$6:$H$605,5,Expenses!$A$6:$A$605,">="&DATE(Settings!$B$6,1,1),Expenses!$A$6:$A$605,"<="&DATE(Settings!$B$6,12,31)) -> 0 | G24: =SUMIFS(Expenses!$E$6:$E$605,Expenses!$D$6:$D$605,$A24,Expenses!$H$6:$H$605,6,Expenses!$A$6:$A$605,">="&DATE(Settings!$B$6,1,1),Expenses!$A$6:$A$605,"<="&DATE(Settings!$B$6,12,31)) -> 0 | H24: =SUMIFS(Expenses!$E$6:$E$605,Expenses!$D$6:$D$605,$A24,Expenses!$H$6:$H$605,7,Expenses!$A$6:$A$605,">="&DATE(Settings!$B$6,1,1),Expenses!$A$6:$A$605,"<="&DATE(Settings!$B$6,12,31)) -> 0 | I24: =SUMIFS(Expenses!$E$6:$E$605,Expenses!$D$6:$D$605,$A24,Expenses!$H$6:$H$605,8,Expenses!$A$6:$A$605,">="&DATE(Settings!$B$6,1,1),Expenses!$A$6:$A$605,"<="&DATE(Settings!$B$6,12,31)) -> 0 | J24: =SUMIFS(Expenses!$E$6:$E$605,Expenses!$D$6:$D$605,$A24,Expenses!$H$6:$H$605,9,Expenses!$A$6:$A$605,">="&DATE(Settings!$B$6,1,1),Expenses!$A$6:$A$605,"<="&DATE(Settings!$B$6,12,31)) -> 0 | K24: =SUMIFS(Expenses!$E$6:$E$605,Expenses!$D$6:$D$605,$A24,Expenses!$H$6:$H$605,10,Expenses!$A$6:$A$605,">="&DATE(Settings!$B$6,1,1),Expenses!$A$6:$A$605,"<="&DATE(Settings!$B$6,12,31)) -> 0 | L24: =SUMIFS(Expenses!$E$6:$E$605,Expenses!$D$6:$D$605,$A24,Expenses!$H$6:$H$605,11,Expenses!$A$6:$A$605,">="&DATE(Settings!$B$6,1,1),Expenses!$A$6:$A$605,"<="&DATE(Settings!$B$6,12,31)) -> 0 | M24: =SUMIFS(Expenses!$E$6:$E$605,Expenses!$D$6:$D$605,$A24,Expenses!$H$6:$H$605,12,Expenses!$A$6:$A$605,">="&DATE(Settings!$B$6,1,1),Expenses!$A$6:$A$605,"<="&DATE(Settings!$B$6,12,31)) -> 0 | N24: =SUM(B24:M24) -> 0
A25: =Settings!D18 -> Marketing | B25: =SUMIFS(Expenses!$E$6:$E$605,Expenses!$D$6:$D$605,$A25,Expenses!$H$6:$H$605,1,Expenses!$A$6:$A$605,">="&DATE(Settings!$B$6,1,1),Expenses!$A$6:$A$605,"<="&DATE(Settings!$B$6,12,31)) -> 0 | C25: =SUMIFS(Expenses!$E$6:$E$605,Expenses!$D$6:$D$605,$A25,Expenses!$H$6:$H$605,2,Expenses!$A$6:$A$605,">="&DATE(Settings!$B$6,1,1),Expenses!$A$6:$A$605,"<="&DATE(Settings!$B$6,12,31)) -> 0 | D25: =SUMIFS(Expenses!$E$6:$E$605,Expenses!$D$6:$D$605,$A25,Expenses!$H$6:$H$605,3,Expenses!$A$6:$A$605,">="&DATE(Settings!$B$6,1,1),Expenses!$A$6:$A$605,"<="&DATE(Settings!$B$6,12,31)) -> 0 | E25: =SUMIFS(Expenses!$E$6:$E$605,Expenses!$D$6:$D$605,$A25,Expenses!$H$6:$H$605,4,Expenses!$A$6:$A$605,">="&DATE(Settings!$B$6,1,1),Expenses!$A$6:$A$605,"<="&DATE(Settings!$B$6,12,31)) -> 0 | F25: =SUMIFS(Expenses!$E$6:$E$605,Expenses!$D$6:$D$605,$A25,Expenses!$H$6:$H$605,5,Expenses!$A$6:$A$605,">="&DATE(Settings!$B$6,1,1),Expenses!$A$6:$A$605,"<="&DATE(Settings!$B$6,12,31)) -> 0 | G25: =SUMIFS(Expenses!$E$6:$E$605,Expenses!$D$6:$D$605,$A25,Expenses!$H$6:$H$605,6,Expenses!$A$6:$A$605,">="&DATE(Settings!$B$6,1,1),Expenses!$A$6:$A$605,"<="&DATE(Settings!$B$6,12,31)) -> 0 | H25: =SUMIFS(Expenses!$E$6:$E$605,Expenses!$D$6:$D$605,$A25,Expenses!$H$6:$H$605,7,Expenses!$A$6:$A$605,">="&DATE(Settings!$B$6,1,1),Expenses!$A$6:$A$605,"<="&DATE(Settings!$B$6,12,31)) -> 0 | I25: =SUMIFS(Expenses!$E$6:$E$605,Expenses!$D$6:$D$605,$A25,Expenses!$H$6:$H$605,8,Expenses!$A$6:$A$605,">="&DATE(Settings!$B$6,1,1),Expenses!$A$6:$A$605,"<="&DATE(Settings!$B$6,12,31)) -> 0 | J25: =SUMIFS(Expenses!$E$6:$E$605,Expenses!$D$6:$D$605,$A25,Expenses!$H$6:$H$605,9,Expenses!$A$6:$A$605,">="&DATE(Settings!$B$6,1,1),Expenses!$A$6:$A$605,"<="&DATE(Settings!$B$6,12,31)) -> 0 | K25: =SUMIFS(Expenses!$E$6:$E$605,Expenses!$D$6:$D$605,$A25,Expenses!$H$6:$H$605,10,Expenses!$A$6:$A$605,">="&DATE(Settings!$B$6,1,1),Expenses!$A$6:$A$605,"<="&DATE(Settings!$B$6,12,31)) -> 0 | L25: =SUMIFS(Expenses!$E$6:$E$605,Expenses!$D$6:$D$605,$A25,Expenses!$H$6:$H$605,11,Expenses!$A$6:$A$605,">="&DATE(Settings!$B$6,1,1),Expenses!$A$6:$A$605,"<="&DATE(Settings!$B$6,12,31)) -> 0 | M25: =SUMIFS(Expenses!$E$6:$E$605,Expenses!$D$6:$D$605,$A25,Expenses!$H$6:$H$605,12,Expenses!$A$6:$A$605,">="&DATE(Settings!$B$6,1,1),Expenses!$A$6:$A$605,"<="&DATE(Settings!$B$6,12,31)) -> 0 | N25: =SUM(B25:M25) -> 0
A26: =Settings!D19 -> Education | B26: =SUMIFS(Expenses!$E$6:$E$605,Expenses!$D$6:$D$605,$A26,Expenses!$H$6:$H$605,1,Expenses!$A$6:$A$605,">="&DATE(Settings!$B$6,1,1),Expenses!$A$6:$A$605,"<="&DATE(Settings!$B$6,12,31)) -> 0 | C26: =SUMIFS(Expenses!$E$6:$E$605,Expenses!$D$6:$D$605,$A26,Expenses!$H$6:$H$605,2,Expenses!$A$6:$A$605,">="&DATE(Settings!$B$6,1,1),Expenses!$A$6:$A$605,"<="&DATE(Settings!$B$6,12,31)) -> 0 | D26: =SUMIFS(Expenses!$E$6:$E$605,Expenses!$D$6:$D$605,$A26,Expenses!$H$6:$H$605,3,Expenses!$A$6:$A$605,">="&DATE(Settings!$B$6,1,1),Expenses!$A$6:$A$605,"<="&DATE(Settings!$B$6,12,31)) -> 0 | E26: =SUMIFS(Expenses!$E$6:$E$605,Expenses!$D$6:$D$605,$A26,Expenses!$H$6:$H$605,4,Expenses!$A$6:$A$605,">="&DATE(Settings!$B$6,1,1),Expenses!$A$6:$A$605,"<="&DATE(Settings!$B$6,12,31)) -> 0 | F26: =SUMIFS(Expenses!$E$6:$E$605,Expenses!$D$6:$D$605,$A26,Expenses!$H$6:$H$605,5,Expenses!$A$6:$A$605,">="&DATE(Settings!$B$6,1,1),Expenses!$A$6:$A$605,"<="&DATE(Settings!$B$6,12,31)) -> 0 | G26: =SUMIFS(Expenses!$E$6:$E$605,Expenses!$D$6:$D$605,$A26,Expenses!$H$6:$H$605,6,Expenses!$A$6:$A$605,">="&DATE(Settings!$B$6,1,1),Expenses!$A$6:$A$605,"<="&DATE(Settings!$B$6,12,31)) -> 0 | H26: =SUMIFS(Expenses!$E$6:$E$605,Expenses!$D$6:$D$605,$A26,Expenses!$H$6:$H$605,7,Expenses!$A$6:$A$605,">="&DATE(Settings!$B$6,1,1),Expenses!$A$6:$A$605,"<="&DATE(Settings!$B$6,12,31)) -> 0 | I26: =SUMIFS(Expenses!$E$6:$E$605,Expenses!$D$6:$D$605,$A26,Expenses!$H$6:$H$605,8,Expenses!$A$6:$A$605,">="&DATE(Settings!$B$6,1,1),Expenses!$A$6:$A$605,"<="&DATE(Settings!$B$6,12,31)) -> 0 | J26: =SUMIFS(Expenses!$E$6:$E$605,Expenses!$D$6:$D$605,$A26,Expenses!$H$6:$H$605,9,Expenses!$A$6:$A$605,">="&DATE(Settings!$B$6,1,1),Expenses!$A$6:$A$605,"<="&DATE(Settings!$B$6,12,31)) -> 0 | K26: =SUMIFS(Expenses!$E$6:$E$605,Expenses!$D$6:$D$605,$A26,Expenses!$H$6:$H$605,10,Expenses!$A$6:$A$605,">="&DATE(Settings!$B$6,1,1),Expenses!$A$6:$A$605,"<="&DATE(Settings!$B$6,12,31)) -> 0 | L26: =SUMIFS(Expenses!$E$6:$E$605,Expenses!$D$6:$D$605,$A26,Expenses!$H$6:$H$605,11,Expenses!$A$6:$A$605,">="&DATE(Settings!$B$6,1,1),Expenses!$A$6:$A$605,"<="&DATE(Settings!$B$6,12,31)) -> 0 | M26: =SUMIFS(Expenses!$E$6:$E$605,Expenses!$D$6:$D$605,$A26,Expenses!$H$6:$H$605,12,Expenses!$A$6:$A$605,">="&DATE(Settings!$B$6,1,1),Expenses!$A$6:$A$605,"<="&DATE(Settings!$B$6,12,31)) -> 0 | N26: =SUM(B26:M26) -> 0
A27: =Settings!D20 -> Laundry and cleaning | B27: =SUMIFS(Expenses!$E$6:$E$605,Expenses!$D$6:$D$605,$A27,Expenses!$H$6:$H$605,1,Expenses!$A$6:$A$605,">="&DATE(Settings!$B$6,1,1),Expenses!$A$6:$A$605,"<="&DATE(Settings!$B$6,12,31)) -> 0 | C27: =SUMIFS(Expenses!$E$6:$E$605,Expenses!$D$6:$D$605,$A27,Expenses!$H$6:$H$605,2,Expenses!$A$6:$A$605,">="&DATE(Settings!$B$6,1,1),Expenses!$A$6:$A$605,"<="&DATE(Settings!$B$6,12,31)) -> 0 | D27: =SUMIFS(Expenses!$E$6:$E$605,Expenses!$D$6:$D$605,$A27,Expenses!$H$6:$H$605,3,Expenses!$A$6:$A$605,">="&DATE(Settings!$B$6,1,1),Expenses!$A$6:$A$605,"<="&DATE(Settings!$B$6,12,31)) -> 0 | E27: =SUMIFS(Expenses!$E$6:$E$605,Expenses!$D$6:$D$605,$A27,Expenses!$H$6:$H$605,4,Expenses!$A$6:$A$605,">="&DATE(Settings!$B$6,1,1),Expenses!$A$6:$A$605,"<="&DATE(Settings!$B$6,12,31)) -> 0 | F27: =SUMIFS(Expenses!$E$6:$E$605,Expenses!$D$6:$D$605,$A27,Expenses!$H$6:$H$605,5,Expenses!$A$6:$A$605,">="&DATE(Settings!$B$6,1,1),Expenses!$A$6:$A$605,"<="&DATE(Settings!$B$6,12,31)) -> 0 | G27: =SUMIFS(Expenses!$E$6:$E$605,Expenses!$D$6:$D$605,$A27,Expenses!$H$6:$H$605,6,Expenses!$A$6:$A$605,">="&DATE(Settings!$B$6,1,1),Expenses!$A$6:$A$605,"<="&DATE(Settings!$B$6,12,31)) -> 0 | H27: =SUMIFS(Expenses!$E$6:$E$605,Expenses!$D$6:$D$605,$A27,Expenses!$H$6:$H$605,7,Expenses!$A$6:$A$605,">="&DATE(Settings!$B$6,1,1),Expenses!$A$6:$A$605,"<="&DATE(Settings!$B$6,12,31)) -> 0 | I27: =SUMIFS(Expenses!$E$6:$E$605,Expenses!$D$6:$D$605,$A27,Expenses!$H$6:$H$605,8,Expenses!$A$6:$A$605,">="&DATE(Settings!$B$6,1,1),Expenses!$A$6:$A$605,"<="&DATE(Settings!$B$6,12,31)) -> 0 | J27: =SUMIFS(Expenses!$E$6:$E$605,Expenses!$D$6:$D$605,$A27,Expenses!$H$6:$H$605,9,Expenses!$A$6:$A$605,">="&DATE(Settings!$B$6,1,1),Expenses!$A$6:$A$605,"<="&DATE(Settings!$B$6,12,31)) -> 0 | K27: =SUMIFS(Expenses!$E$6:$E$605,Expenses!$D$6:$D$605,$A27,Expenses!$H$6:$H$605,10,Expenses!$A$6:$A$605,">="&DATE(Settings!$B$6,1,1),Expenses!$A$6:$A$605,"<="&DATE(Settings!$B$6,12,31)) -> 0 | L27: =SUMIFS(Expenses!$E$6:$E$605,Expenses!$D$6:$D$605,$A27,Expenses!$H$6:$H$605,11,Expenses!$A$6:$A$605,">="&DATE(Settings!$B$6,1,1),Expenses!$A$6:$A$605,"<="&DATE(Settings!$B$6,12,31)) -> 0 | M27: =SUMIFS(Expenses!$E$6:$E$605,Expenses!$D$6:$D$605,$A27,Expenses!$H$6:$H$605,12,Expenses!$A$6:$A$605,">="&DATE(Settings!$B$6,1,1),Expenses!$A$6:$A$605,"<="&DATE(Settings!$B$6,12,31)) -> 0 | N27: =SUM(B27:M27) -> 0
A28: =Settings!D21 -> Bank fees | B28: =SUMIFS(Expenses!$E$6:$E$605,Expenses!$D$6:$D$605,$A28,Expenses!$H$6:$H$605,1,Expenses!$A$6:$A$605,">="&DATE(Settings!$B$6,1,1),Expenses!$A$6:$A$605,"<="&DATE(Settings!$B$6,12,31)) -> 0 | C28: =SUMIFS(Expenses!$E$6:$E$605,Expenses!$D$6:$D$605,$A28,Expenses!$H$6:$H$605,2,Expenses!$A$6:$A$605,">="&DATE(Settings!$B$6,1,1),Expenses!$A$6:$A$605,"<="&DATE(Settings!$B$6,12,31)) -> 0 | D28: =SUMIFS(Expenses!$E$6:$E$605,Expenses!$D$6:$D$605,$A28,Expenses!$H$6:$H$605,3,Expenses!$A$6:$A$605,">="&DATE(Settings!$B$6,1,1),Expenses!$A$6:$A$605,"<="&DATE(Settings!$B$6,12,31)) -> 0 | E28: =SUMIFS(Expenses!$E$6:$E$605,Expenses!$D$6:$D$605,$A28,Expenses!$H$6:$H$605,4,Expenses!$A$6:$A$605,">="&DATE(Settings!$B$6,1,1),Expenses!$A$6:$A$605,"<="&DATE(Settings!$B$6,12,31)) -> 0 | F28: =SUMIFS(Expenses!$E$6:$E$605,Expenses!$D$6:$D$605,$A28,Expenses!$H$6:$H$605,5,Expenses!$A$6:$A$605,">="&DATE(Settings!$B$6,1,1),Expenses!$A$6:$A$605,"<="&DATE(Settings!$B$6,12,31)) -> 0 | G28: =SUMIFS(Expenses!$E$6:$E$605,Expenses!$D$6:$D$605,$A28,Expenses!$H$6:$H$605,6,Expenses!$A$6:$A$605,">="&DATE(Settings!$B$6,1,1),Expenses!$A$6:$A$605,"<="&DATE(Settings!$B$6,12,31)) -> 0 | H28: =SUMIFS(Expenses!$E$6:$E$605,Expenses!$D$6:$D$605,$A28,Expenses!$H$6:$H$605,7,Expenses!$A$6:$A$605,">="&DATE(Settings!$B$6,1,1),Expenses!$A$6:$A$605,"<="&DATE(Settings!$B$6,12,31)) -> 0 | I28: =SUMIFS(Expenses!$E$6:$E$605,Expenses!$D$6:$D$605,$A28,Expenses!$H$6:$H$605,8,Expenses!$A$6:$A$605,">="&DATE(Settings!$B$6,1,1),Expenses!$A$6:$A$605,"<="&DATE(Settings!$B$6,12,31)) -> 0 | J28: =SUMIFS(Expenses!$E$6:$E$605,Expenses!$D$6:$D$605,$A28,Expenses!$H$6:$H$605,9,Expenses!$A$6:$A$605,">="&DATE(Settings!$B$6,1,1),Expenses!$A$6:$A$605,"<="&DATE(Settings!$B$6,12,31)) -> 0 | K28: =SUMIFS(Expenses!$E$6:$E$605,Expenses!$D$6:$D$605,$A28,Expenses!$H$6:$H$605,10,Expenses!$A$6:$A$605,">="&DATE(Settings!$B$6,1,1),Expenses!$A$6:$A$605,"<="&DATE(Settings!$B$6,12,31)) -> 0 | L28: =SUMIFS(Expenses!$E$6:$E$605,Expenses!$D$6:$D$605,$A28,Expenses!$H$6:$H$605,11,Expenses!$A$6:$A$605,">="&DATE(Settings!$B$6,1,1),Expenses!$A$6:$A$605,"<="&DATE(Settings!$B$6,12,31)) -> 0 | M28: =SUMIFS(Expenses!$E$6:$E$605,Expenses!$D$6:$D$605,$A28,Expenses!$H$6:$H$605,12,Expenses!$A$6:$A$605,">="&DATE(Settings!$B$6,1,1),Expenses!$A$6:$A$605,"<="&DATE(Settings!$B$6,12,31)) -> 0 | N28: =SUM(B28:M28) -> 0
A29: =Settings!D22 -> Phone and internet | B29: =SUMIFS(Expenses!$E$6:$E$605,Expenses!$D$6:$D$605,$A29,Expenses!$H$6:$H$605,1,Expenses!$A$6:$A$605,">="&DATE(Settings!$B$6,1,1),Expenses!$A$6:$A$605,"<="&DATE(Settings!$B$6,12,31)) -> 0 | C29: =SUMIFS(Expenses!$E$6:$E$605,Expenses!$D$6:$D$605,$A29,Expenses!$H$6:$H$605,2,Expenses!$A$6:$A$605,">="&DATE(Settings!$B$6,1,1),Expenses!$A$6:$A$605,"<="&DATE(Settings!$B$6,12,31)) -> 0 | D29: =SUMIFS(Expenses!$E$6:$E$605,Expenses!$D$6:$D$605,$A29,Expenses!$H$6:$H$605,3,Expenses!$A$6:$A$605,">="&DATE(Settings!$B$6,1,1),Expenses!$A$6:$A$605,"<="&DATE(Settings!$B$6,12,31)) -> 0 | E29: =SUMIFS(Expenses!$E$6:$E$605,Expenses!$D$6:$D$605,$A29,Expenses!$H$6:$H$605,4,Expenses!$A$6:$A$605,">="&DATE(Settings!$B$6,1,1),Expenses!$A$6:$A$605,"<="&DATE(Settings!$B$6,12,31)) -> 0 | F29: =SUMIFS(Expenses!$E$6:$E$605,Expenses!$D$6:$D$605,$A29,Expenses!$H$6:$H$605,5,Expenses!$A$6:$A$605,">="&DATE(Settings!$B$6,1,1),Expenses!$A$6:$A$605,"<="&DATE(Settings!$B$6,12,31)) -> 0 | G29: =SUMIFS(Expenses!$E$6:$E$605,Expenses!$D$6:$D$605,$A29,Expenses!$H$6:$H$605,6,Expenses!$A$6:$A$605,">="&DATE(Settings!$B$6,1,1),Expenses!$A$6:$A$605,"<="&DATE(Settings!$B$6,12,31)) -> 0 | H29: =SUMIFS(Expenses!$E$6:$E$605,Expenses!$D$6:$D$605,$A29,Expenses!$H$6:$H$605,7,Expenses!$A$6:$A$605,">="&DATE(Settings!$B$6,1,1),Expenses!$A$6:$A$605,"<="&DATE(Settings!$B$6,12,31)) -> 0 | I29: =SUMIFS(Expenses!$E$6:$E$605,Expenses!$D$6:$D$605,$A29,Expenses!$H$6:$H$605,8,Expenses!$A$6:$A$605,">="&DATE(Settings!$B$6,1,1),Expenses!$A$6:$A$605,"<="&DATE(Settings!$B$6,12,31)) -> 0 | J29: =SUMIFS(Expenses!$E$6:$E$605,Expenses!$D$6:$D$605,$A29,Expenses!$H$6:$H$605,9,Expenses!$A$6:$A$605,">="&DATE(Settings!$B$6,1,1),Expenses!$A$6:$A$605,"<="&DATE(Settings!$B$6,12,31)) -> 0 | K29: =SUMIFS(Expenses!$E$6:$E$605,Expenses!$D$6:$D$605,$A29,Expenses!$H$6:$H$605,10,Expenses!$A$6:$A$605,">="&DATE(Settings!$B$6,1,1),Expenses!$A$6:$A$605,"<="&DATE(Settings!$B$6,12,31)) -> 0 | L29: =SUMIFS(Expenses!$E$6:$E$605,Expenses!$D$6:$D$605,$A29,Expenses!$H$6:$H$605,11,Expenses!$A$6:$A$605,">="&DATE(Settings!$B$6,1,1),Expenses!$A$6:$A$605,"<="&DATE(Settings!$B$6,12,31)) -> 0 | M29: =SUMIFS(Expenses!$E$6:$E$605,Expenses!$D$6:$D$605,$A29,Expenses!$H$6:$H$605,12,Expenses!$A$6:$A$605,">="&DATE(Settings!$B$6,1,1),Expenses!$A$6:$A$605,"<="&DATE(Settings!$B$6,12,31)) -> 0 | N29: =SUM(B29:M29) -> 0
A30: =Settings!D23 -> Car and mileage | B30: =SUMIFS(Expenses!$E$6:$E$605,Expenses!$D$6:$D$605,$A30,Expenses!$H$6:$H$605,1,Expenses!$A$6:$A$605,">="&DATE(Settings!$B$6,1,1),Expenses!$A$6:$A$605,"<="&DATE(Settings!$B$6,12,31)) -> 0 | C30: =SUMIFS(Expenses!$E$6:$E$605,Expenses!$D$6:$D$605,$A30,Expenses!$H$6:$H$605,2,Expenses!$A$6:$A$605,">="&DATE(Settings!$B$6,1,1),Expenses!$A$6:$A$605,"<="&DATE(Settings!$B$6,12,31)) -> 0 | D30: =SUMIFS(Expenses!$E$6:$E$605,Expenses!$D$6:$D$605,$A30,Expenses!$H$6:$H$605,3,Expenses!$A$6:$A$605,">="&DATE(Settings!$B$6,1,1),Expenses!$A$6:$A$605,"<="&DATE(Settings!$B$6,12,31)) -> 0 | E30: =SUMIFS(Expenses!$E$6:$E$605,Expenses!$D$6:$D$605,$A30,Expenses!$H$6:$H$605,4,Expenses!$A$6:$A$605,">="&DATE(Settings!$B$6,1,1),Expenses!$A$6:$A$605,"<="&DATE(Settings!$B$6,12,31)) -> 0 | F30: =SUMIFS(Expenses!$E$6:$E$605,Expenses!$D$6:$D$605,$A30,Expenses!$H$6:$H$605,5,Expenses!$A$6:$A$605,">="&DATE(Settings!$B$6,1,1),Expenses!$A$6:$A$605,"<="&DATE(Settings!$B$6,12,31)) -> 0 | G30: =SUMIFS(Expenses!$E$6:$E$605,Expenses!$D$6:$D$605,$A30,Expenses!$H$6:$H$605,6,Expenses!$A$6:$A$605,">="&DATE(Settings!$B$6,1,1),Expenses!$A$6:$A$605,"<="&DATE(Settings!$B$6,12,31)) -> 0 | H30: =SUMIFS(Expenses!$E$6:$E$605,Expenses!$D$6:$D$605,$A30,Expenses!$H$6:$H$605,7,Expenses!$A$6:$A$605,">="&DATE(Settings!$B$6,1,1),Expenses!$A$6:$A$605,"<="&DATE(Settings!$B$6,12,31)) -> 0 | I30: =SUMIFS(Expenses!$E$6:$E$605,Expenses!$D$6:$D$605,$A30,Expenses!$H$6:$H$605,8,Expenses!$A$6:$A$605,">="&DATE(Settings!$B$6,1,1),Expenses!$A$6:$A$605,"<="&DATE(Settings!$B$6,12,31)) -> 0 | J30: =SUMIFS(Expenses!$E$6:$E$605,Expenses!$D$6:$D$605,$A30,Expenses!$H$6:$H$605,9,Expenses!$A$6:$A$605,">="&DATE(Settings!$B$6,1,1),Expenses!$A$6:$A$605,"<="&DATE(Settings!$B$6,12,31)) -> 0 | K30: =SUMIFS(Expenses!$E$6:$E$605,Expenses!$D$6:$D$605,$A30,Expenses!$H$6:$H$605,10,Expenses!$A$6:$A$605,">="&DATE(Settings!$B$6,1,1),Expenses!$A$6:$A$605,"<="&DATE(Settings!$B$6,12,31)) -> 0 | L30: =SUMIFS(Expenses!$E$6:$E$605,Expenses!$D$6:$D$605,$A30,Expenses!$H$6:$H$605,11,Expenses!$A$6:$A$605,">="&DATE(Settings!$B$6,1,1),Expenses!$A$6:$A$605,"<="&DATE(Settings!$B$6,12,31)) -> 0 | M30: =SUMIFS(Expenses!$E$6:$E$605,Expenses!$D$6:$D$605,$A30,Expenses!$H$6:$H$605,12,Expenses!$A$6:$A$605,">="&DATE(Settings!$B$6,1,1),Expenses!$A$6:$A$605,"<="&DATE(Settings!$B$6,12,31)) -> 0 | N30: =SUM(B30:M30) -> 0
